Workbook

Sheet Sheet1
A1: 楽天ポイント集計Excel | F1: 2026 | G1: 年 | H1: 6 | I1: 月 | O1: ダイヤモンド会員 | X1: Rakuten UN-LIMIT VII | AO1: =+AO625 -> 0 | AP1: =+AP625 -> 0
A3: 購入データ入力 | O3: 条件入力欄 | AI3: 個別② | AJ3: 基本 | AK3: SPU | AL3: 基本 | AM3: SPU | AN3: SPU | AO3: マラソン | AP3: マラソン | AQ3: マラソン | AR3: ポイントアップ祭り | AS3: 個別① | AT3: 個別① | AU3: ポイント | AV3: 特定日 | AW3: 特定日 | AX3: 特定日 | AY3: 個別② | AZ3: 個別② | BA3: 個別② | BB3: 個別② | BC3: 個別② | BD3: 個別② | BE3: 個別② | BF3: 個別② | BG3: 個別② | BH3: 個別② | BI3: 個別② | BJ3: SPU | BK3: SPU | BL3: SPU | BM3: SPU | BN3: SPU | BO3: SPU | BP3: SPU | BQ3: SPU | BR3: SPU | BS3: SPU | BT3: SPU | BU3: SPU | BV3: SPU | BW3: SPU | BX3: 個別① | BY3: 個別① | BZ3: 個別① | CA3: 個別① | CB3: 個別① | CC3: 個別① | CD3: 個別① | CE3: 個別① | CF3: 個別①
A4: 購入年月日 | B4: 購入先 | C4: 商品名 | D4: 商品名(型番) | E4: URL | F4: 単価 | G4: 個数 | H4: 価格 | I4: 値引 | J4: 送料 | K4: ポイント計算ベース100円 税込 | L4: ポイント計算ベース100円 税込 | M4: ポイント計算ベース200円 税抜 | N4: 請求額 | O4: 火・木 プレミアムカードデー | P4: 5の日 | Q4: ワンダフル | R4: 18日 | S4: イーグルス等 | T4: ママ割 | U4: マイカー割 | V4: リピート | W4: 直前 | X4: 39ショップ | AD4: マラソン判定① | AE4: マラソン判定② | AF4: マラソン判定③ | AG4: マラソン判定④ | AI4: 店舗 | AJ4: 基本還元率 | AK4: 楽天モバイル＋会員ランク特典 | AL4: 楽天カード 通常分 | AM4: 楽天カード 特典分 | AN4: 楽天銀行＋楽天カード（引落） | AO4: マラソン① | AP4: マラソン② | AQ4: マラソン③ | AR4: ポイントアップ祭り | AS4: イーグルス他 | AT4: 39ショップ | AU4: 火・木 プレミアムカードデー | AV4: 5の日 | AW4: ワンダフル | AX4: 18日 | AY4: スーパーDEAL | BA4: 店舗 | BB4: カード | BJ4: 楽天モバイルキャリア決済 | BK4: 楽天ひかり | BL4: 楽天プレミアムカード特典分 | BM4: 楽天銀行＋楽天カード(給与等) | BN4: 楽天証券 投資信託 | BO4: 楽天証券 米国株式 | BP4: 楽天ウォレット | BQ4: 楽天トラベル | BR4: 楽天市場アプリ | BS4: 楽天ブックス | BT4: 楽天kobo | BU4: Rakuten Pasha | BV4: Rakuten Fashionアプリ | BW4: 楽天ビューティ | BX4: ママ割 | BY4: マイカー割 | BZ4: リピート割 | CA4: 直前 | CG4: 合計ポイント | CH4: 実質購入金額 | CI4: 実質購入単価 | CK4: ASIN | CL4: Amazon等販売先URL | CM4: 出品価格 | CN4: "入金 予定[円/個]" | CO4: 予定利益/個 | CR4: 予定総利益 | CU4: SKU例
A5: 倍率 | AJ5: 1 | AK5: 3 | AL5: 1 | AM5: 1 | AN5: 0.3 | AO5: =+IF(COUNTA(AD$11:AD$624)-COUNTBLANK(AD$11:AD$624)-1>=9,9,IF(COUNTA(AD$11:AD$624)-COUNTBLANK(AD$11:AD$624)-1<0,0,COUNTA(AD$11:AD$624)-COUNTBLANK(AD$11:AD$624)-1)) -> 0 | AP5: =+IF(COUNTA(AE$11:AE$624)-COUNTBLANK(AE$11:AE$624)-1>=9,9,IF(COUNTA(AE$11:AE$624)-COUNTBLANK(AE$11:AE$624)-1<0,0,COUNTA(AE$11:AE$624)-COUNTBLANK(AE$11:AE$624)-1)) -> 0 | AQ5: =+IF(COUNTA(AF$11:AF$624)-COUNTBLANK(AF$11:AF$624)-1>=9,9,IF(COUNTA(AF$11:AF$624)-COUNTBLANK(AF$11:AF$624)-1<0,0,COUNTA(AF$11:AF$624)-COUNTBLANK(AF$11:AF$624)-1)) -> 0 | AR5: =IF(SUMIFS($H$11:$H$624,$A$11:$A$624,">="&$AR$8,$A$11:$A$624,"<="&$AR$9)+SUMIFS($I$11:$I$624,$A$11:$A$624,">="&$AR$8,$A$11:$A$624,"<="&$AR$9)>=45000,6,IF(SUMIFS($H$11:$H$624,$A$11:$A$624,">="&$AR$8,$A$11:$A$624,"<="&$AR$9)+SUMIFS($I$11:$I$624,$A$11:$A$624,">="&$AR$8,$A$11:$A$624,"<="&$AR$9)>=30000,4,IF(SUMIFS($H$11:$H$624,$A$11:$A$624,">="&$AR$8,$A$11:$A$624,"<="&$AR$9)+SUMIFS($I$11:$I$624,$A$11:$A$624,">="&$AR$8,$A$11:$A$624,"<="&$AR$9)>=10000,2,IF(SUMIFS($H$11:$H$624,$A$11:$A$624,">="&$AR$8,$A$11:$A$624,"<="&$AR$9)+SUMIFS($I$11:$I$624,$A$11:$A$624,">="&$AR$8,$A$11:$A$624,"<="&$AR$9)>=5000,1,"")))) | AS5: - | AT5: 1 | AU5: 1 | AV5: 2 | AW5: 3 | AX5: =VLOOKUP($O$1,[1]マスタ!$B$1:$D$5,3,0) -> 3 | BJ5: 0.5 | BK5: 1 | BL5: 2 | BM5: 0.5 | BN5: 0.5 | BO5: 0.5 | BP5: 0.5 | BQ5: 1 | BR5: 0.5 | BS5: 0.5 | BT5: 0.5 | BU5: 0.5 | BV5: 0.5 | BW5: 0.5 | BX5: 1 | BY5: 2 | BZ5: 1 | CA5: 1
A6: 上限 | AJ6: 99999999 | AK6: 2000 | AL6: 99999999 | AM6: 5000 | AN6: 1000 | AO6: 7000 | AP6: 7000 | AQ6: 7000 | AR6: 5000 | AS6: - | AT6: 3000 | AU6: 10000 | AV6: 3000 | AW6: 1000 | AX6: 1000 | BJ6: 5000 | BK6: 5000 | BL6: 15000 | BM6: 5000 | BN6: 5000 | BO6: 5000 | BP6: 5000 | BQ6: =+SUMIFS([1]マスタ!$C$1:$C$5,[1]マスタ!$B$1:$B$5,$O$1) -> #VALUE! | BR6: =+SUMIFS([1]マスタ!$C$1:$C$5,[1]マスタ!$B$1:$B$5,$O$1) -> #VALUE! | BS6: =+SUMIFS([1]マスタ!$C$1:$C$5,[1]マスタ!$B$1:$B$5,$O$1) -> #VALUE! | BT6: =+SUMIFS([1]マスタ!$C$1:$C$5,[1]マスタ!$B$1:$B$5,$O$1) -> #VALUE! | BU6: 5000 | BV6: =+SUMIFS([1]マスタ!$C$1:$C$5,[1]マスタ!$B$1:$B$5,$O$1) -> #VALUE! | BW6: =+SUMIFS([1]マスタ!$C$1:$C$5,[1]マスタ!$B$1:$B$5,$O$1) -> #VALUE! | BX6: 1000 | BY6: 1000 | BZ6: 1000 | CA6: 1000
A7: 判定 | AJ7: ○ | AK7: ○ | AL7: ○ | AM7: ○ | AN7: ○ | BJ7: ✕ | BK7: ✕ | BL7: ✕ | BM7: ✕ | BN7: ✕ | BO7: ✕ | BP7: ✕ | BQ7: ✕ | BR7: ✕ | BS7: ✕ | BT7: ✕ | BU7: ✕ | BV7: ✕ | BW7: ✕
A8: 開始 | AJ8: =+DATE($F$1,$H$1,1) -> 46174 | AK8: =+DATE($F$1,$H$1,1) -> 46174 | AL8: =+DATE($F$1,$H$1,1) -> 46174 | AM8: =+DATE($F$1,$H$1,1) -> 46174 | AN8: =+DATE($F$1,$H$1,1) -> 46174 | AO8: 46177 | AP8: 46193 | AR8: 46023 | AS8: =+DATE($F$1,$H$1,1) -> 46174 | AT8: 46177 | AU8: =+DATE($F$1,$H$1,1) -> 46174 | AV8: =+DATE($F$1,$H$1,1) -> 46174 | AW8: =+DATE($F$1,$H$1,1) -> 46174 | AX8: =+DATE($F$1,$H$1,1) -> 46174 | BJ8: =+DATE($F$1,$H$1,1) -> 46174 | BK8: =+DATE($F$1,$H$1,1) -> 46174 | BL8: =+DATE($F$1,$H$1,1) -> 46174 | BM8: =+DATE($F$1,$H$1,1) -> 46174 | BN8: =+DATE($F$1,$H$1,1) -> 46174 | BO8: =+DATE($F$1,$H$1,1) -> 46174 | BP8: =+DATE($F$1,$H$1,1) -> 46174 | BQ8: =+DATE($F$1,$H$1,1) -> 46174 | ... CA8: =+DATE($F$1,$H$1,1) -> 46174
A9: 終了 | AJ9: =+EOMONTH(AJ8,0) -> 46203 | AK9: =+EOMONTH(AK8,0) -> 46203 | AL9: =+EOMONTH(AL8,0) -> 46203 | AM9: =+EOMONTH(AM8,0) -> 46203 | AN9: =+EOMONTH(AN8,0) -> 46203 | AO9: 46184 | AP9: 46199 | AR9: 46027 | AS9: =+EOMONTH(AS8,0) -> 46203 | AT9: 46184 | AU9: =+EOMONTH(AU8,0) -> 46203 | AV9: =+EOMONTH(AV8,0) -> 46203 | AW9: =+EOMONTH(AW8,0) -> 46203 | AX9: =+EOMONTH(AX8,0) -> 46203 | BJ9: =+EOMONTH(BJ8,0) -> 46203 | BK9: =+EOMONTH(BK8,0) -> 46203 | BL9: =+EOMONTH(BL8,0) -> 46203 | BM9: =+EOMONTH(BM8,0) -> 46203 | BN9: =+EOMONTH(BN8,0) -> 46203 | BO9: =+EOMONTH(BO8,0) -> 46203 | BP9: =+EOMONTH(BP8,0) -> 46203 | BQ9: =+EOMONTH(BQ8,0) -> 46203 | ... CA9: =+EOMONTH(CA8,0) -> 46203
G11: 1 | H11: =+F11*G11 -> 0 | K11: =+ROUNDDOWN((H11+I11)/100,0)*100 -> 0 | L11: =+ROUNDDOWN((H11+I11)/1.1/100,0)*100 -> 0 | M11: =+ROUNDDOWN((H11+I11)/1.1/200,0)*200 -> 0 | N11: =+H11+I11+J11 -> 0 | O11: =IF(OR(WEEKDAY($A11,2)=2,WEEKDAY($A11,2)=4),"○","✕") -> ✕ | P11: =+IF(MOD(TEXT($A11,"DD"),5)=0,"○","✕") -> ○ | Q11: =+IF((TEXT($A11,"DD")+0)=1,"○","✕") -> ✕ | R11: =+IF((TEXT($A11,"DD")+0)=18,"○","✕") -> ✕ | S11: 0 | T11: ✕ | U11: ✕ | V11: ✕ | W11: ✕ | X11: ○ | Y11: ✕ | Z11: ✕ | AA11: ✕ | AB11: ✕ | AC11: ✕ | AD11: =+IF(ISERROR(VLOOKUP($B11,AD$10:AD10,1,0)),IF(AND($N11>=1000,$A11>=AO$8,$A11<=AO$9),$B11,""),"") | AE11: =+IF(ISERROR(VLOOKUP($B11,AE$10:AE10,1,0)),IF(AND($N11>=1000,$A11>=AP$8,$A11<=AP$9),$B11,""),"") | AF11: =+IF(ISERROR(VLOOKUP($B11,AF$10:AF10,1,0)),IF(AND($N11>=1000,$A11>=AQ$8,$A11<=AQ$9),$B11,""),"") | AG11: =+IF(ISERROR(VLOOKUP($B11,AG$10:AG10,1,0)),IF(AND($N11>=1000,$A11>=AR$8,$A11<=AR$9),$B11,""),"") | AI11: 0 | AJ11: =IF(AND(AJ$7="○",$A11>=AJ$8,$A11<=AJ$9),IF(SUM(AJ$10:AJ10)-ROUNDDOWN($K11*AJ$5/100,0)<-AJ$6,-AJ$6-SUM(AJ$10:AJ10),-ROUNDDOWN($K11*AJ$5/100,0)),0) -> 0 | AK11: =IF(AND(AK$7="○",$A11>=AK$8,$A11<=AK$9),IF(SUM(AK$10:AK10)-ROUNDDOWN($L11*AK$5/100,0)<-AK$6,-AK$6-SUM(AK$10:AK10),-ROUNDDOWN($L11*AK$5/100,0)),0) -> 0 | AL11: =IF(AND(AL$7="○",$A11>=AL$8,$A11<=AL$9),IF(SUM(AL$10:AL10)-ROUNDDOWN($N11*AL$5/100,0)<-AL$6,-AL$6-SUM(AL$10:AL10),-ROUNDDOWN($N11*AL$5/100,0)),0) -> 0 | AM11: =IF(AND(AM$7="○",$A11>=AM$8,$A11<=AM$9),IF(SUM(AM$10:AM10)-ROUNDDOWN($L11*AM$5/100,0)<-AM$6,-AM$6-SUM(AM$10:AM10),-ROUNDDOWN($L11*AM$5/100,0)),0) -> 0 | AN11: =IF(AND(AN$7="○",$A11>=AN$8,$A11<=AN$9),IF(SUM(AN$10:AN10)-ROUNDDOWN($M11*AN$5/100,0)<-AN$6,-AN$6-SUM(AN$10:AN10),-ROUNDDOWN($M11*AN$5/100,0)),0) -> 0 | AO11: =IF(AND($A11>=AO$8,$A11<=AO$9),IF(SUM(AO$10:AO10)-ROUNDDOWN($K11*AO$5/100,0)<-AO$6,-AO$6-SUM(AO$10:AO10),-ROUNDDOWN($K11*AO$5/100,0)),0) -> 0 | AP11: =IF(AND($A11>=AP$8,$A11<=AP$9),IF(SUM(AP$10:AP10)-ROUNDDOWN($K11*AP$5/100,0)<-AP$6,-AP$6-SUM(AP$10:AP10),-ROUNDDOWN($K11*AP$5/100,0)),0) -> 0 | AQ11: =IF(AND($A11>=AQ$8,$A11<=AQ$9),IF(SUM(AQ$10:AQ10)-ROUNDDOWN($K11*AQ$5/100,0)<-AQ$6,-AQ$6-SUM(AQ$10:AQ10),-ROUNDDOWN($K11*AQ$5/100,0)),0) -> 0 | AR11: =IF(AND($A11>=AR$8,$A11<=AR$9),IF(SUM(AR$10:AR10)-ROUNDDOWN($K11*AR$5/100,0)<-AR$6,-AR$6-SUM(AR$10:AR10),-ROUNDDOWN($K11*AR$5/100,0)),0) -> 0 | AS11: =IF(SUMIFS(AS$10:AS10,$A$10:$A10,$A11)-ROUNDDOWN($K11*$S11/100,0)<-$S11*1000,-$S11*1000-SUMIFS(AS$10:AS10,$A$10:$A10,$A11),-ROUNDDOWN($K11*$S11/100,0)) -> 0 | AT11: =IF(AND(X11="○",$A11>=AT$8,$A11<=AT$9,K11>=3980),IF(SUM(AT$10:AT10)-ROUNDDOWN($K11*AT$5/100,0)<-AT$6,-AT$6-SUM(AT$10:AT10),-ROUNDDOWN($K11*AT$5/100,0)),0) -> 0 | AU11: =IF(O11="○",IF(SUM(AU$10:AU10)-ROUNDDOWN($K11*AU$5/100,0)<-AU$6,-AU$6-SUM(AU$10:AU10),-ROUNDDOWN($K11*AU$5/100,0)),0) -> 0 | AV11: =IF(P11="○",IF(SUM(AV$10:AV10)-ROUNDDOWN($K11*AV$5/100,0)<-AV$6,-AV$6-SUM(AV$10:AV10),-ROUNDDOWN($K11*AV$5/100,0)),0) -> 0 | AW11: =IF(Q11="○",IF(SUM(AW$10:AW10)-ROUNDDOWN($K11*AW$5/100,0)<-AW$6,-AW$6-SUM(AW$10:AW10),-ROUNDDOWN($K11*AW$5/100,0)),0) -> 0 | AX11: =IF(R11="○",IF(SUM(AX$10:AX10)-ROUNDDOWN($K11*AX$5/100,0)<-AX$6,-AX$6-SUM(AX$10:AX10),-ROUNDDOWN($K11*AX$5/100,0)),0) -> 0 | AY11: 0 | AZ11: =-ROUNDDOWN($K11*AY11/100,0) -> 0 | BA11: =-ROUNDDOWN($K11*AI11/100,0) -> 0 | BC11: =-ROUNDDOWN($K11*BB11/100,0) -> 0 | BD11: 0 | BE11: =-ROUNDDOWN($K11*BD11/100,0) -> 0 | BF11: 0 | BG11: =-ROUNDDOWN($K11*BF11/100,0) -> 0 | BH11: 0 | BI11: =-ROUNDDOWN($K11*BH11/100,0) -> 0 | BJ11: =IF(AND(BJ$7="○",$A11>=BJ$8,$A11<=BJ$9),IF(SUM(BJ$10:BJ10)-ROUNDDOWN($M11*BJ$5/100,0)<-BJ$6,-BJ$6-SUM(BJ$10:BJ10),-ROUNDDOWN($M11*BJ$5/100,0)),0) -> 0 | BK11: =IF(AND(BK$7="○",$A11>=BK$8,$A11<=BK$9),IF(SUM(BK$10:BK10)-ROUNDDOWN($L11*BK$5/100,0)<-BK$6,-BK$6-SUM(BK$10:BK10),-ROUNDDOWN($L11*BK$5/100,0)),0) -> 0 | BL11: =IF(AND(BL$7="○",$A11>=BL$8,$A11<=BL$9),IF(SUM(BL$10:BL10)-ROUNDDOWN($L11*BL$5/100,0)<-BL$6,-BL$6-SUM(BL$10:BL10),-ROUNDDOWN($L11*BL$5/100,0)),0) -> 0 | BM11: =IF(AND(BM$7="○",$A11>=BM$8,$A11<=BM$9),IF(SUM(BM$10:BM10)-ROUNDDOWN($M11*BM$5/100,0)<-BM$6,-BM$6-SUM(BM$10:BM10),-ROUNDDOWN($M11*BM$5/100,0)),0) -> 0 | BN11: =IF(AND(BN$7="○",$A11>=BN$8,$A11<=BN$9),IF(SUM(BN$10:BN10)-ROUNDDOWN($M11*BN$5/100,0)<-BN$6,-BN$6-SUM(BN$10:BN10),-ROUNDDOWN($M11*BN$5/100,0)),0) -> 0 | BO11: =IF(AND(BO$7="○",$A11>=BO$8,$A11<=BO$9),IF(SUM(BO$10:BO10)-ROUNDDOWN($M11*BO$5/100,0)<-BO$6,-BO$6-SUM(BO$10:BO10),-ROUNDDOWN($M11*BO$5/100,0)),0) -> 0 | BP11: =IF(AND(BP$7="○",$A11>=BP$8,$A11<=BP$9),IF(SUM(BP$10:BP10)-ROUNDDOWN($M11*BP$5/100,0)<-BP$6,-BP$6-SUM(BP$10:BP10),-ROUNDDOWN($M11*BP$5/100,0)),0) -> 0 | BQ11: =IF(AND(BQ$7="○",$A11>=BQ$8,$A11<=BQ$9),IF(SUM(BQ$10:BQ10)-ROUNDDOWN($L11*BQ$5/100,0)<-BQ$6,-BQ$6-SUM(BQ$10:BQ10),-ROUNDDOWN($L11*BQ$5/100,0)),0) -> 0 | BR11: =IF(AND(BR$7="○",$A11>=BR$8,$A11<=BR$9),IF(SUM(BR$10:BR10)-ROUNDDOWN($M11*BR$5/100,0)<-BR$6,-BR$6-SUM(BR$10:BR10),-ROUNDDOWN($M11*BR$5/100,0)),0) -> 0 | BS11: =IF(AND(BS$7="○",$A11>=BS$8,$A11<=BS$9),IF(SUM(BS$10:BS10)-ROUNDDOWN($M11*BS$5/100,0)<-BS$6,-BS$6-SUM(BS$10:BS10),-ROUNDDOWN($M11*BS$5/100,0)),0) -> 0 | BT11: =IF(AND(BT$7="○",$A11>=BT$8,$A11<=BT$9),IF(SUM(BT$10:BT10)-ROUNDDOWN($M11*BT$5/100,0)<-BT$6,-BT$6-SUM(BT$10:BT10),-ROUNDDOWN($M11*BT$5/100,0)),0) -> 0 | BU11: =IF(AND(BU$7="○",$A11>=BU$8,$A11<=BU$9),IF(SUM(BU$10:BU10)-ROUNDDOWN($M11*BU$5/100,0)<-BU$6,-BU$6-SUM(BU$10:BU10),-ROUNDDOWN($M11*BU$5/100,0)),0) -> 0 | BV11: =IF(AND(BV$7="○",$A11>=BV$8,$A11<=BV$9),IF(SUM(BV$10:BV10)-ROUNDDOWN($M11*BV$5/100,0)<-BV$6,-BV$6-SUM(BV$10:BV10),-ROUNDDOWN($M11*BV$5/100,0)),0) -> 0 | BW11: =IF(AND(BW$7="○",$A11>=BW$8,$A11<=BW$9),IF(SUM(BW$10:BW10)-ROUNDDOWN($M11*BW$5/100,0)<-BW$6,-BW$6-SUM(BW$10:BW10),-ROUNDDOWN($M11*BW$5/100,0)),0) -> 0 | BX11: =IF(AND(T11="○",$A11>=BX$8,$A11<=BX$9),IF(SUM(BX$10:BX10)-ROUNDDOWN($K11*BX$5/100,0)<-BX$6,-BX$6-SUM(BX$10:BX10),-ROUNDDOWN($K11*BX$5/100,0)),0) -> 0 | BY11: =IF(AND(U11="○",$A11>=BY$8,$A11<=BY$9),IF(SUM(BY$10:BY10)-ROUNDDOWN($K11*BY$5/100,0)<-BY$6,-BY$6-SUM(BY$10:BY10),-ROUNDDOWN($K11*BY$5/100,0)),0) -> 0 | BZ11: =IF(AND(V11="○",$A11>=BZ$8,$A11<=BZ$9),IF(SUM(BZ$10:BZ10)-ROUNDDOWN($K11*BZ$5/100,0)<-BZ$6,-BZ$6-SUM(BZ$10:BZ10),-ROUNDDOWN($K11*BZ$5/100,0)),0) -> 0 | CA11: =IF(AND(W11="○",$A11>=CA$8,$A11<=CA$9),IF(SUM(CA$10:CA10)-ROUNDDOWN($K11*CA$5/100,0)<-CA$6,-CA$6-SUM(CA$10:CA10),-ROUNDDOWN($K11*CA$5/100,0)),0) -> 0 | CG11: =+SUM(AJ11:CF11,BC11,BE11,AZ11,BA11,BG11,BI11) -> 0 | CH11: =+CG11+N11 -> 0 | CI11: =IFERROR(ROUNDDOWN((CH11/G11),0),0) -> 0 | CO11: =IFERROR(CN11-CI11,0) -> 0 | CP11: =IFERROR(CN11/CI11,0) -> 0 | CR11: =+CO11*G11 -> 0 | CT11: =INDEX([2]マスタ!$A:$A,MATCH(D11,[2]マスタ!$C:$C,0)) -> #N/A | CU11: =IFERROR(TEXT(TODAY(),"yyyymmdd")&"_"&ROUNDDOWN(H11+I11,0)&"-"&ROUNDDOWN(CI11,0),"") -> 20260620_0-0
G12: 1 | H12: =+F12*G12 -> 0 | K12: =+ROUNDDOWN((H12+I12)/100,0)*100 -> 0 | L12: =+ROUNDDOWN((H12+I12)/1.1/100,0)*100 -> 0 | M12: =+ROUNDDOWN((H12+I12)/1.1/200,0)*200 -> 0 | N12: =+H12+I12+J12 -> 0 | O12: =IF(OR(WEEKDAY($A12,2)=2,WEEKDAY($A12,2)=4),"○","✕") -> ✕ | P12: =+IF(MOD(TEXT($A12,"DD"),5)=0,"○","✕") -> ○ | Q12: =+IF((TEXT($A12,"DD")+0)=1,"○","✕") -> ✕ | R12: =+IF((TEXT($A12,"DD")+0)=18,"○","✕") -> ✕ | S12: 0 | T12: ✕ | U12: ✕ | V12: ✕ | W12: ✕ | X12: ○ | Y12: ✕ | Z12: ✕ | AA12: ✕ | AB12: ✕ | AC12: ✕ | AD12: =+IF(ISERROR(VLOOKUP($B12,AD$10:AD11,1,0)),IF(AND($N12>=1000,$A12>=AO$8,$A12<=AO$9),$B12,""),"") | AE12: =+IF(ISERROR(VLOOKUP($B12,AE$10:AE11,1,0)),IF(AND($N12>=1000,$A12>=AP$8,$A12<=AP$9),$B12,""),"") | AF12: =+IF(ISERROR(VLOOKUP($B12,AF$10:AF11,1,0)),IF(AND($N12>=1000,$A12>=AQ$8,$A12<=AQ$9),$B12,""),"") | AG12: =+IF(ISERROR(VLOOKUP($B12,AG$10:AG11,1,0)),IF(AND($N12>=1000,$A12>=AR$8,$A12<=AR$9),$B12,""),"") | AI12: 0 | AJ12: =IF(AND(AJ$7="○",$A12>=AJ$8,$A12<=AJ$9),IF(SUM(AJ$10:AJ11)-ROUNDDOWN($K12*AJ$5/100,0)<-AJ$6,-AJ$6-SUM(AJ$10:AJ11),-ROUNDDOWN($K12*AJ$5/100,0)),0) -> 0 | AK12: =IF(AND(AK$7="○",$A12>=AK$8,$A12<=AK$9),IF(SUM(AK$10:AK11)-ROUNDDOWN($L12*AK$5/100,0)<-AK$6,-AK$6-SUM(AK$10:AK11),-ROUNDDOWN($L12*AK$5/100,0)),0) -> 0 | AL12: =IF(AND(AL$7="○",$A12>=AL$8,$A12<=AL$9),IF(SUM(AL$10:AL11)-ROUNDDOWN($N12*AL$5/100,0)<-AL$6,-AL$6-SUM(AL$10:AL11),-ROUNDDOWN($N12*AL$5/100,0)),0) -> 0 | AM12: =IF(AND(AM$7="○",$A12>=AM$8,$A12<=AM$9),IF(SUM(AM$10:AM11)-ROUNDDOWN($L12*AM$5/100,0)<-AM$6,-AM$6-SUM(AM$10:AM11),-ROUNDDOWN($L12*AM$5/100,0)),0) -> 0 | AN12: =IF(AND(AN$7="○",$A12>=AN$8,$A12<=AN$9),IF(SUM(AN$10:AN11)-ROUNDDOWN($M12*AN$5/100,0)<-AN$6,-AN$6-SUM(AN$10:AN11),-ROUNDDOWN($M12*AN$5/100,0)),0) -> 0 | AO12: =IF(AND($A12>=AO$8,$A12<=AO$9),IF(SUM(AO$10:AO11)-ROUNDDOWN($K12*AO$5/100,0)<-AO$6,-AO$6-SUM(AO$10:AO11),-ROUNDDOWN($K12*AO$5/100,0)),0) -> 0 | AP12: =IF(AND($A12>=AP$8,$A12<=AP$9),IF(SUM(AP$10:AP11)-ROUNDDOWN($K12*AP$5/100,0)<-AP$6,-AP$6-SUM(AP$10:AP11),-ROUNDDOWN($K12*AP$5/100,0)),0) -> 0 | AQ12: =IF(AND($A12>=AQ$8,$A12<=AQ$9),IF(SUM(AQ$10:AQ11)-ROUNDDOWN($K12*AQ$5/100,0)<-AQ$6,-AQ$6-SUM(AQ$10:AQ11),-ROUNDDOWN($K12*AQ$5/100,0)),0) -> 0 | AR12: =IF(AND($A12>=AR$8,$A12<=AR$9),IF(SUM(AR$10:AR11)-ROUNDDOWN($K12*AR$5/100,0)<-AR$6,-AR$6-SUM(AR$10:AR11),-ROUNDDOWN($K12*AR$5/100,0)),0) -> 0 | AS12: =IF(SUMIFS(AS$10:AS11,$A$10:$A11,$A12)-ROUNDDOWN($K12*$S12/100,0)<-$S12*1000,-$S12*1000-SUMIFS(AS$10:AS11,$A$10:$A11,$A12),-ROUNDDOWN($K12*$S12/100,0)) -> 0 | AT12: =IF(AND(X12="○",$A12>=AT$8,$A12<=AT$9,K12>=3980),IF(SUM(AT$10:AT11)-ROUNDDOWN($K12*AT$5/100,0)<-AT$6,-AT$6-SUM(AT$10:AT11),-ROUNDDOWN($K12*AT$5/100,0)),0) -> 0 | AU12: =IF(O12="○",IF(SUM(AU$10:AU11)-ROUNDDOWN($K12*AU$5/100,0)<-AU$6,-AU$6-SUM(AU$10:AU11),-ROUNDDOWN($K12*AU$5/100,0)),0) -> 0 | AV12: =IF(P12="○",IF(SUM(AV$10:AV11)-ROUNDDOWN($K12*AV$5/100,0)<-AV$6,-AV$6-SUM(AV$10:AV11),-ROUNDDOWN($K12*AV$5/100,0)),0) -> 0 | AW12: =IF(Q12="○",IF(SUM(AW$10:AW11)-ROUNDDOWN($K12*AW$5/100,0)<-AW$6,-AW$6-SUM(AW$10:AW11),-ROUNDDOWN($K12*AW$5/100,0)),0) -> 0 | AX12: =IF(R12="○",IF(SUM(AX$10:AX11)-ROUNDDOWN($K12*AX$5/100,0)<-AX$6,-AX$6-SUM(AX$10:AX11),-ROUNDDOWN($K12*AX$5/100,0)),0) -> 0 | AY12: 0 | AZ12: =-ROUNDDOWN($K12*AY12/100,0) -> 0 | BA12: =-ROUNDDOWN($K12*AI12/100,0) -> 0 | BC12: =-ROUNDDOWN($K12*BB12/100,0) -> 0 | BD12: 0 | BE12: =-ROUNDDOWN($K12*BD12/100,0) -> 0 | BF12: 0 | BG12: =-ROUNDDOWN($K12*BF12/100,0) -> 0 | BH12: 0 | BI12: =-ROUNDDOWN($K12*BH12/100,0) -> 0 | BJ12: =IF(AND(BJ$7="○",$A12>=BJ$8,$A12<=BJ$9),IF(SUM(BJ$10:BJ11)-ROUNDDOWN($M12*BJ$5/100,0)<-BJ$6,-BJ$6-SUM(BJ$10:BJ11),-ROUNDDOWN($M12*BJ$5/100,0)),0) -> 0 | BK12: =IF(AND(BK$7="○",$A12>=BK$8,$A12<=BK$9),IF(SUM(BK$10:BK11)-ROUNDDOWN($L12*BK$5/100,0)<-BK$6,-BK$6-SUM(BK$10:BK11),-ROUNDDOWN($L12*BK$5/100,0)),0) -> 0 | BL12: =IF(AND(BL$7="○",$A12>=BL$8,$A12<=BL$9),IF(SUM(BL$10:BL11)-ROUNDDOWN($L12*BL$5/100,0)<-BL$6,-BL$6-SUM(BL$10:BL11),-ROUNDDOWN($L12*BL$5/100,0)),0) -> 0 | BM12: =IF(AND(BM$7="○",$A12>=BM$8,$A12<=BM$9),IF(SUM(BM$10:BM11)-ROUNDDOWN($M12*BM$5/100,0)<-BM$6,-BM$6-SUM(BM$10:BM11),-ROUNDDOWN($M12*BM$5/100,0)),0) -> 0 | BN12: =IF(AND(BN$7="○",$A12>=BN$8,$A12<=BN$9),IF(SUM(BN$10:BN11)-ROUNDDOWN($M12*BN$5/100,0)<-BN$6,-BN$6-SUM(BN$10:BN11),-ROUNDDOWN($M12*BN$5/100,0)),0) -> 0 | BO12: =IF(AND(BO$7="○",$A12>=BO$8,$A12<=BO$9),IF(SUM(BO$10:BO11)-ROUNDDOWN($M12*BO$5/100,0)<-BO$6,-BO$6-SUM(BO$10:BO11),-ROUNDDOWN($M12*BO$5/100,0)),0) -> 0 | BP12: =IF(AND(BP$7="○",$A12>=BP$8,$A12<=BP$9),IF(SUM(BP$10:BP11)-ROUNDDOWN($M12*BP$5/100,0)<-BP$6,-BP$6-SUM(BP$10:BP11),-ROUNDDOWN($M12*BP$5/100,0)),0) -> 0 | BQ12: =IF(AND(BQ$7="○",$A12>=BQ$8,$A12<=BQ$9),IF(SUM(BQ$10:BQ11)-ROUNDDOWN($L12*BQ$5/100,0)<-BQ$6,-BQ$6-SUM(BQ$10:BQ11),-ROUNDDOWN($L12*BQ$5/100,0)),0) -> 0 | BR12: =IF(AND(BR$7="○",$A12>=BR$8,$A12<=BR$9),IF(SUM(BR$10:BR11)-ROUNDDOWN($M12*BR$5/100,0)<-BR$6,-BR$6-SUM(BR$10:BR11),-ROUNDDOWN($M12*BR$5/100,0)),0) -> 0 | BS12: =IF(AND(BS$7="○",$A12>=BS$8,$A12<=BS$9),IF(SUM(BS$10:BS11)-ROUNDDOWN($M12*BS$5/100,0)<-BS$6,-BS$6-SUM(BS$10:BS11),-ROUNDDOWN($M12*BS$5/100,0)),0) -> 0 | BT12: =IF(AND(BT$7="○",$A12>=BT$8,$A12<=BT$9),IF(SUM(BT$10:BT11)-ROUNDDOWN($M12*BT$5/100,0)<-BT$6,-BT$6-SUM(BT$10:BT11),-ROUNDDOWN($M12*BT$5/100,0)),0) -> 0 | BU12: =IF(AND(BU$7="○",$A12>=BU$8,$A12<=BU$9),IF(SUM(BU$10:BU11)-ROUNDDOWN($M12*BU$5/100,0)<-BU$6,-BU$6-SUM(BU$10:BU11),-ROUNDDOWN($M12*BU$5/100,0)),0) -> 0 | BV12: =IF(AND(BV$7="○",$A12>=BV$8,$A12<=BV$9),IF(SUM(BV$10:BV11)-ROUNDDOWN($M12*BV$5/100,0)<-BV$6,-BV$6-SUM(BV$10:BV11),-ROUNDDOWN($M12*BV$5/100,0)),0) -> 0 | BW12: =IF(AND(BW$7="○",$A12>=BW$8,$A12<=BW$9),IF(SUM(BW$10:BW11)-ROUNDDOWN($M12*BW$5/100,0)<-BW$6,-BW$6-SUM(BW$10:BW11),-ROUNDDOWN($M12*BW$5/100,0)),0) -> 0 | BX12: =IF(AND(T12="○",$A12>=BX$8,$A12<=BX$9),IF(SUM(BX$10:BX11)-ROUNDDOWN($K12*BX$5/100,0)<-BX$6,-BX$6-SUM(BX$10:BX11),-ROUNDDOWN($K12*BX$5/100,0)),0) -> 0 | BY12: =IF(AND(U12="○",$A12>=BY$8,$A12<=BY$9),IF(SUM(BY$10:BY11)-ROUNDDOWN($K12*BY$5/100,0)<-BY$6,-BY$6-SUM(BY$10:BY11),-ROUNDDOWN($K12*BY$5/100,0)),0) -> 0 | BZ12: =IF(AND(V12="○",$A12>=BZ$8,$A12<=BZ$9),IF(SUM(BZ$10:BZ11)-ROUNDDOWN($K12*BZ$5/100,0)<-BZ$6,-BZ$6-SUM(BZ$10:BZ11),-ROUNDDOWN($K12*BZ$5/100,0)),0) -> 0 | CA12: =IF(AND(W12="○",$A12>=CA$8,$A12<=CA$9),IF(SUM(CA$10:CA11)-ROUNDDOWN($K12*CA$5/100,0)<-CA$6,-CA$6-SUM(CA$10:CA11),-ROUNDDOWN($K12*CA$5/100,0)),0) -> 0 | CG12: =+SUM(AJ12:CF12,BC12,BE12,AZ12,BA12,BG12,BI12) -> 0 | CH12: =+CG12+N12 -> 0 | CI12: =IFERROR(ROUNDDOWN((CH12/G12),0),0) -> 0 | CO12: =IFERROR(CN12-CI12,0) -> 0 | CP12: =IFERROR(CN12/CI12,0) -> 0 | CR12: =+CO12*G12 -> 0 | CT12: =INDEX([2]マスタ!$A:$A,MATCH(D12,[2]マスタ!$C:$C,0)) -> #N/A | CU12: =IFERROR(TEXT(TODAY(),"yyyymmdd")&"_"&ROUNDDOWN(H12+I12,0)&"-"&ROUNDDOWN(CI12,0),"") -> 20260620_0-0
G13: 1 | H13: =+F13*G13 -> 0 | K13: =+ROUNDDOWN((H13+I13)/100,0)*100 -> 0 | L13: =+ROUNDDOWN((H13+I13)/1.1/100,0)*100 -> 0 | M13: =+ROUNDDOWN((H13+I13)/1.1/200,0)*200 -> 0 | N13: =+H13+I13+J13 -> 0 | O13: =IF(OR(WEEKDAY($A13,2)=2,WEEKDAY($A13,2)=4),"○","✕") -> ✕ | P13: =+IF(MOD(TEXT($A13,"DD"),5)=0,"○","✕") -> ○ | Q13: =+IF((TEXT($A13,"DD")+0)=1,"○","✕") -> ✕ | R13: =+IF((TEXT($A13,"DD")+0)=18,"○","✕") -> ✕ | S13: 0 | T13: ✕ | U13: ✕ | V13: ✕ | W13: ✕ | X13: ○ | Y13: ✕ | Z13: ✕ | AA13: ✕ | AB13: ✕ | AC13: ✕ | AD13: =+IF(ISERROR(VLOOKUP($B13,AD$10:AD12,1,0)),IF(AND($N13>=1000,$A13>=AO$8,$A13<=AO$9),$B13,""),"") | AE13: =+IF(ISERROR(VLOOKUP($B13,AE$10:AE12,1,0)),IF(AND($N13>=1000,$A13>=AP$8,$A13<=AP$9),$B13,""),"") | AF13: =+IF(ISERROR(VLOOKUP($B13,AF$10:AF12,1,0)),IF(AND($N13>=1000,$A13>=AQ$8,$A13<=AQ$9),$B13,""),"") | AG13: =+IF(ISERROR(VLOOKUP($B13,AG$10:AG12,1,0)),IF(AND($N13>=1000,$A13>=AR$8,$A13<=AR$9),$B13,""),"") | AI13: 0 | AJ13: =IF(AND(AJ$7="○",$A13>=AJ$8,$A13<=AJ$9),IF(SUM(AJ$10:AJ12)-ROUNDDOWN($K13*AJ$5/100,0)<-AJ$6,-AJ$6-SUM(AJ$10:AJ12),-ROUNDDOWN($K13*AJ$5/100,0)),0) -> 0 | AK13: =IF(AND(AK$7="○",$A13>=AK$8,$A13<=AK$9),IF(SUM(AK$10:AK12)-ROUNDDOWN($L13*AK$5/100,0)<-AK$6,-AK$6-SUM(AK$10:AK12),-ROUNDDOWN($L13*AK$5/100,0)),0) -> 0 | AL13: =IF(AND(AL$7="○",$A13>=AL$8,$A13<=AL$9),IF(SUM(AL$10:AL12)-ROUNDDOWN($N13*AL$5/100,0)<-AL$6,-AL$6-SUM(AL$10:AL12),-ROUNDDOWN($N13*AL$5/100,0)),0) -> 0 | AM13: =IF(AND(AM$7="○",$A13>=AM$8,$A13<=AM$9),IF(SUM(AM$10:AM12)-ROUNDDOWN($L13*AM$5/100,0)<-AM$6,-AM$6-SUM(AM$10:AM12),-ROUNDDOWN($L13*AM$5/100,0)),0) -> 0 | AN13: =IF(AND(AN$7="○",$A13>=AN$8,$A13<=AN$9),IF(SUM(AN$10:AN12)-ROUNDDOWN($M13*AN$5/100,0)<-AN$6,-AN$6-SUM(AN$10:AN12),-ROUNDDOWN($M13*AN$5/100,0)),0) -> 0 | AO13: =IF(AND($A13>=AO$8,$A13<=AO$9),IF(SUM(AO$10:AO12)-ROUNDDOWN($K13*AO$5/100,0)<-AO$6,-AO$6-SUM(AO$10:AO12),-ROUNDDOWN($K13*AO$5/100,0)),0) -> 0 | AP13: =IF(AND($A13>=AP$8,$A13<=AP$9),IF(SUM(AP$10:AP12)-ROUNDDOWN($K13*AP$5/100,0)<-AP$6,-AP$6-SUM(AP$10:AP12),-ROUNDDOWN($K13*AP$5/100,0)),0) -> 0 | AQ13: =IF(AND($A13>=AQ$8,$A13<=AQ$9),IF(SUM(AQ$10:AQ12)-ROUNDDOWN($K13*AQ$5/100,0)<-AQ$6,-AQ$6-SUM(AQ$10:AQ12),-ROUNDDOWN($K13*AQ$5/100,0)),0) -> 0 | AR13: =IF(AND($A13>=AR$8,$A13<=AR$9),IF(SUM(AR$10:AR12)-ROUNDDOWN($K13*AR$5/100,0)<-AR$6,-AR$6-SUM(AR$10:AR12),-ROUNDDOWN($K13*AR$5/100,0)),0) -> 0 | AS13: =IF(SUMIFS(AS$10:AS12,$A$10:$A12,$A13)-ROUNDDOWN($K13*$S13/100,0)<-$S13*1000,-$S13*1000-SUMIFS(AS$10:AS12,$A$10:$A12,$A13),-ROUNDDOWN($K13*$S13/100,0)) -> 0 | AT13: =IF(AND(X13="○",$A13>=AT$8,$A13<=AT$9,K13>=3980),IF(SUM(AT$10:AT12)-ROUNDDOWN($K13*AT$5/100,0)<-AT$6,-AT$6-SUM(AT$10:AT12),-ROUNDDOWN($K13*AT$5/100,0)),0) -> 0 | AU13: =IF(O13="○",IF(SUM(AU$10:AU12)-ROUNDDOWN($K13*AU$5/100,0)<-AU$6,-AU$6-SUM(AU$10:AU12),-ROUNDDOWN($K13*AU$5/100,0)),0) -> 0 | AV13: =IF(P13="○",IF(SUM(AV$10:AV12)-ROUNDDOWN($K13*AV$5/100,0)<-AV$6,-AV$6-SUM(AV$10:AV12),-ROUNDDOWN($K13*AV$5/100,0)),0) -> 0 | AW13: =IF(Q13="○",IF(SUM(AW$10:AW12)-ROUNDDOWN($K13*AW$5/100,0)<-AW$6,-AW$6-SUM(AW$10:AW12),-ROUNDDOWN($K13*AW$5/100,0)),0) -> 0 | AX13: =IF(R13="○",IF(SUM(AX$10:AX12)-ROUNDDOWN($K13*AX$5/100,0)<-AX$6,-AX$6-SUM(AX$10:AX12),-ROUNDDOWN($K13*AX$5/100,0)),0) -> 0 | AY13: 0 | AZ13: =-ROUNDDOWN($K13*AY13/100,0) -> 0 | BA13: =-ROUNDDOWN($K13*AI13/100,0) -> 0 | BC13: =-ROUNDDOWN($K13*BB13/100,0) -> 0 | BD13: 0 | BE13: =-ROUNDDOWN($K13*BD13/100,0) -> 0 | BF13: 0 | BG13: =-ROUNDDOWN($K13*BF13/100,0) -> 0 | BH13: 0 | BI13: =-ROUNDDOWN($K13*BH13/100,0) -> 0 | BJ13: =IF(AND(BJ$7="○",$A13>=BJ$8,$A13<=BJ$9),IF(SUM(BJ$10:BJ12)-ROUNDDOWN($M13*BJ$5/100,0)<-BJ$6,-BJ$6-SUM(BJ$10:BJ12),-ROUNDDOWN($M13*BJ$5/100,0)),0) -> 0 | BK13: =IF(AND(BK$7="○",$A13>=BK$8,$A13<=BK$9),IF(SUM(BK$10:BK12)-ROUNDDOWN($L13*BK$5/100,0)<-BK$6,-BK$6-SUM(BK$10:BK12),-ROUNDDOWN($L13*BK$5/100,0)),0) -> 0 | BL13: =IF(AND(BL$7="○",$A13>=BL$8,$A13<=BL$9),IF(SUM(BL$10:BL12)-ROUNDDOWN($L13*BL$5/100,0)<-BL$6,-BL$6-SUM(BL$10:BL12),-ROUNDDOWN($L13*BL$5/100,0)),0) -> 0 | BM13: =IF(AND(BM$7="○",$A13>=BM$8,$A13<=BM$9),IF(SUM(BM$10:BM12)-ROUNDDOWN($M13*BM$5/100,0)<-BM$6,-BM$6-SUM(BM$10:BM12),-ROUNDDOWN($M13*BM$5/100,0)),0) -> 0 | BN13: =IF(AND(BN$7="○",$A13>=BN$8,$A13<=BN$9),IF(SUM(BN$10:BN12)-ROUNDDOWN($M13*BN$5/100,0)<-BN$6,-BN$6-SUM(BN$10:BN12),-ROUNDDOWN($M13*BN$5/100,0)),0) -> 0 | BO13: =IF(AND(BO$7="○",$A13>=BO$8,$A13<=BO$9),IF(SUM(BO$10:BO12)-ROUNDDOWN($M13*BO$5/100,0)<-BO$6,-BO$6-SUM(BO$10:BO12),-ROUNDDOWN($M13*BO$5/100,0)),0) -> 0 | BP13: =IF(AND(BP$7="○",$A13>=BP$8,$A13<=BP$9),IF(SUM(BP$10:BP12)-ROUNDDOWN($M13*BP$5/100,0)<-BP$6,-BP$6-SUM(BP$10:BP12),-ROUNDDOWN($M13*BP$5/100,0)),0) -> 0 | BQ13: =IF(AND(BQ$7="○",$A13>=BQ$8,$A13<=BQ$9),IF(SUM(BQ$10:BQ12)-ROUNDDOWN($L13*BQ$5/100,0)<-BQ$6,-BQ$6-SUM(BQ$10:BQ12),-ROUNDDOWN($L13*BQ$5/100,0)),0) -> 0 | BR13: =IF(AND(BR$7="○",$A13>=BR$8,$A13<=BR$9),IF(SUM(BR$10:BR12)-ROUNDDOWN($M13*BR$5/100,0)<-BR$6,-BR$6-SUM(BR$10:BR12),-ROUNDDOWN($M13*BR$5/100,0)),0) -> 0 | BS13: =IF(AND(BS$7="○",$A13>=BS$8,$A13<=BS$9),IF(SUM(BS$10:BS12)-ROUNDDOWN($M13*BS$5/100,0)<-BS$6,-BS$6-SUM(BS$10:BS12),-ROUNDDOWN($M13*BS$5/100,0)),0) -> 0 | BT13: =IF(AND(BT$7="○",$A13>=BT$8,$A13<=BT$9),IF(SUM(BT$10:BT12)-ROUNDDOWN($M13*BT$5/100,0)<-BT$6,-BT$6-SUM(BT$10:BT12),-ROUNDDOWN($M13*BT$5/100,0)),0) -> 0 | BU13: =IF(AND(BU$7="○",$A13>=BU$8,$A13<=BU$9),IF(SUM(BU$10:BU12)-ROUNDDOWN($M13*BU$5/100,0)<-BU$6,-BU$6-SUM(BU$10:BU12),-ROUNDDOWN($M13*BU$5/100,0)),0) -> 0 | BV13: =IF(AND(BV$7="○",$A13>=BV$8,$A13<=BV$9),IF(SUM(BV$10:BV12)-ROUNDDOWN($M13*BV$5/100,0)<-BV$6,-BV$6-SUM(BV$10:BV12),-ROUNDDOWN($M13*BV$5/100,0)),0) -> 0 | BW13: =IF(AND(BW$7="○",$A13>=BW$8,$A13<=BW$9),IF(SUM(BW$10:BW12)-ROUNDDOWN($M13*BW$5/100,0)<-BW$6,-BW$6-SUM(BW$10:BW12),-ROUNDDOWN($M13*BW$5/100,0)),0) -> 0 | BX13: =IF(AND(T13="○",$A13>=BX$8,$A13<=BX$9),IF(SUM(BX$10:BX12)-ROUNDDOWN($K13*BX$5/100,0)<-BX$6,-BX$6-SUM(BX$10:BX12),-ROUNDDOWN($K13*BX$5/100,0)),0) -> 0 | BY13: =IF(AND(U13="○",$A13>=BY$8,$A13<=BY$9),IF(SUM(BY$10:BY12)-ROUNDDOWN($K13*BY$5/100,0)<-BY$6,-BY$6-SUM(BY$10:BY12),-ROUNDDOWN($K13*BY$5/100,0)),0) -> 0 | BZ13: =IF(AND(V13="○",$A13>=BZ$8,$A13<=BZ$9),IF(SUM(BZ$10:BZ12)-ROUNDDOWN($K13*BZ$5/100,0)<-BZ$6,-BZ$6-SUM(BZ$10:BZ12),-ROUNDDOWN($K13*BZ$5/100,0)),0) -> 0 | CA13: =IF(AND(W13="○",$A13>=CA$8,$A13<=CA$9),IF(SUM(CA$10:CA12)-ROUNDDOWN($K13*CA$5/100,0)<-CA$6,-CA$6-SUM(CA$10:CA12),-ROUNDDOWN($K13*CA$5/100,0)),0) -> 0 | CG13: =+SUM(AJ13:CF13,BC13,BE13,AZ13,BA13,BG13,BI13) -> 0 | CH13: =+CG13+N13 -> 0 | CI13: =IFERROR(ROUNDDOWN((CH13/G13),0),0) -> 0 | CO13: =IFERROR(CN13-CI13,0) -> 0 | CP13: =IFERROR(CN13/CI13,0) -> 0 | CR13: =+CO13*G13 -> 0 | CT13: =INDEX([2]マスタ!$A:$A,MATCH(D13,[2]マスタ!$C:$C,0)) -> #N/A | CU13: =IFERROR(TEXT(TODAY(),"yyyymmdd")&"_"&ROUNDDOWN(H13+I13,0)&"-"&ROUNDDOWN(CI13,0),"") -> 20260620_0-0
G14: 1 | H14: =+F14*G14 -> 0 | K14: =+ROUNDDOWN((H14+I14)/100,0)*100 -> 0 | L14: =+ROUNDDOWN((H14+I14)/1.1/100,0)*100 -> 0 | M14: =+ROUNDDOWN((H14+I14)/1.1/200,0)*200 -> 0 | N14: =+H14+I14+J14 -> 0 | O14: =IF(OR(WEEKDAY($A14,2)=2,WEEKDAY($A14,2)=4),"○","✕") -> ✕ | P14: =+IF(MOD(TEXT($A14,"DD"),5)=0,"○","✕") -> ○ | Q14: =+IF((TEXT($A14,"DD")+0)=1,"○","✕") -> ✕ | R14: =+IF((TEXT($A14,"DD")+0)=18,"○","✕") -> ✕ | S14: 0 | T14: ✕ | U14: ✕ | V14: ✕ | W14: ✕ | X14: ○ | Y14: ✕ | Z14: ✕ | AA14: ✕ | AB14: ✕ | AC14: ✕ | AD14: =+IF(ISERROR(VLOOKUP($B14,AD$10:AD13,1,0)),IF(AND($N14>=1000,$A14>=AO$8,$A14<=AO$9),$B14,""),"") | AE14: =+IF(ISERROR(VLOOKUP($B14,AE$10:AE13,1,0)),IF(AND($N14>=1000,$A14>=AP$8,$A14<=AP$9),$B14,""),"") | AF14: =+IF(ISERROR(VLOOKUP($B14,AF$10:AF13,1,0)),IF(AND($N14>=1000,$A14>=AQ$8,$A14<=AQ$9),$B14,""),"") | AG14: =+IF(ISERROR(VLOOKUP($B14,AG$10:AG13,1,0)),IF(AND($N14>=1000,$A14>=AR$8,$A14<=AR$9),$B14,""),"") | AI14: 0 | AJ14: =IF(AND(AJ$7="○",$A14>=AJ$8,$A14<=AJ$9),IF(SUM(AJ$10:AJ13)-ROUNDDOWN($K14*AJ$5/100,0)<-AJ$6,-AJ$6-SUM(AJ$10:AJ13),-ROUNDDOWN($K14*AJ$5/100,0)),0) -> 0 | AK14: =IF(AND(AK$7="○",$A14>=AK$8,$A14<=AK$9),IF(SUM(AK$10:AK13)-ROUNDDOWN($L14*AK$5/100,0)<-AK$6,-AK$6-SUM(AK$10:AK13),-ROUNDDOWN($L14*AK$5/100,0)),0) -> 0 | AL14: =IF(AND(AL$7="○",$A14>=AL$8,$A14<=AL$9),IF(SUM(AL$10:AL13)-ROUNDDOWN($N14*AL$5/100,0)<-AL$6,-AL$6-SUM(AL$10:AL13),-ROUNDDOWN($N14*AL$5/100,0)),0) -> 0 | AM14: =IF(AND(AM$7="○",$A14>=AM$8,$A14<=AM$9),IF(SUM(AM$10:AM13)-ROUNDDOWN($L14*AM$5/100,0)<-AM$6,-AM$6-SUM(AM$10:AM13),-ROUNDDOWN($L14*AM$5/100,0)),0) -> 0 | AN14: =IF(AND(AN$7="○",$A14>=AN$8,$A14<=AN$9),IF(SUM(AN$10:AN13)-ROUNDDOWN($M14*AN$5/100,0)<-AN$6,-AN$6-SUM(AN$10:AN13),-ROUNDDOWN($M14*AN$5/100,0)),0) -> 0 | AO14: =IF(AND($A14>=AO$8,$A14<=AO$9),IF(SUM(AO$10:AO13)-ROUNDDOWN($K14*AO$5/100,0)<-AO$6,-AO$6-SUM(AO$10:AO13),-ROUNDDOWN($K14*AO$5/100,0)),0) -> 0 | AP14: =IF(AND($A14>=AP$8,$A14<=AP$9),IF(SUM(AP$10:AP13)-ROUNDDOWN($K14*AP$5/100,0)<-AP$6,-AP$6-SUM(AP$10:AP13),-ROUNDDOWN($K14*AP$5/100,0)),0) -> 0 | AQ14: =IF(AND($A14>=AQ$8,$A14<=AQ$9),IF(SUM(AQ$10:AQ13)-ROUNDDOWN($K14*AQ$5/100,0)<-AQ$6,-AQ$6-SUM(AQ$10:AQ13),-ROUNDDOWN($K14*AQ$5/100,0)),0) -> 0 | AR14: =IF(AND($A14>=AR$8,$A14<=AR$9),IF(SUM(AR$10:AR13)-ROUNDDOWN($K14*AR$5/100,0)<-AR$6,-AR$6-SUM(AR$10:AR13),-ROUNDDOWN($K14*AR$5/100,0)),0) -> 0 | AS14: =IF(SUMIFS(AS$10:AS13,$A$10:$A13,$A14)-ROUNDDOWN($K14*$S14/100,0)<-$S14*1000,-$S14*1000-SUMIFS(AS$10:AS13,$A$10:$A13,$A14),-ROUNDDOWN($K14*$S14/100,0)) -> 0 | AT14: =IF(AND(X14="○",$A14>=AT$8,$A14<=AT$9,K14>=3980),IF(SUM(AT$10:AT13)-ROUNDDOWN($K14*AT$5/100,0)<-AT$6,-AT$6-SUM(AT$10:AT13),-ROUNDDOWN($K14*AT$5/100,0)),0) -> 0 | AU14: =IF(O14="○",IF(SUM(AU$10:AU13)-ROUNDDOWN($K14*AU$5/100,0)<-AU$6,-AU$6-SUM(AU$10:AU13),-ROUNDDOWN($K14*AU$5/100,0)),0) -> 0 | AV14: =IF(P14="○",IF(SUM(AV$10:AV13)-ROUNDDOWN($K14*AV$5/100,0)<-AV$6,-AV$6-SUM(AV$10:AV13),-ROUNDDOWN($K14*AV$5/100,0)),0) -> 0 | AW14: =IF(Q14="○",IF(SUM(AW$10:AW13)-ROUNDDOWN($K14*AW$5/100,0)<-AW$6,-AW$6-SUM(AW$10:AW13),-ROUNDDOWN($K14*AW$5/100,0)),0) -> 0 | AX14: =IF(R14="○",IF(SUM(AX$10:AX13)-ROUNDDOWN($K14*AX$5/100,0)<-AX$6,-AX$6-SUM(AX$10:AX13),-ROUNDDOWN($K14*AX$5/100,0)),0) -> 0 | AY14: 0 | AZ14: =-ROUNDDOWN($K14*AY14/100,0) -> 0 | BA14: =-ROUNDDOWN($K14*AI14/100,0) -> 0 | BC14: =-ROUNDDOWN($K14*BB14/100,0) -> 0 | BD14: 0 | BE14: =-ROUNDDOWN($K14*BD14/100,0) -> 0 | BF14: 0 | BG14: =-ROUNDDOWN($K14*BF14/100,0) -> 0 | BH14: 0 | BI14: =-ROUNDDOWN($K14*BH14/100,0) -> 0 | BJ14: =IF(AND(BJ$7="○",$A14>=BJ$8,$A14<=BJ$9),IF(SUM(BJ$10:BJ13)-ROUNDDOWN($M14*BJ$5/100,0)<-BJ$6,-BJ$6-SUM(BJ$10:BJ13),-ROUNDDOWN($M14*BJ$5/100,0)),0) -> 0 | BK14: =IF(AND(BK$7="○",$A14>=BK$8,$A14<=BK$9),IF(SUM(BK$10:BK13)-ROUNDDOWN($L14*BK$5/100,0)<-BK$6,-BK$6-SUM(BK$10:BK13),-ROUNDDOWN($L14*BK$5/100,0)),0) -> 0 | BL14: =IF(AND(BL$7="○",$A14>=BL$8,$A14<=BL$9),IF(SUM(BL$10:BL13)-ROUNDDOWN($L14*BL$5/100,0)<-BL$6,-BL$6-SUM(BL$10:BL13),-ROUNDDOWN($L14*BL$5/100,0)),0) -> 0 | BM14: =IF(AND(BM$7="○",$A14>=BM$8,$A14<=BM$9),IF(SUM(BM$10:BM13)-ROUNDDOWN($M14*BM$5/100,0)<-BM$6,-BM$6-SUM(BM$10:BM13),-ROUNDDOWN($M14*BM$5/100,0)),0) -> 0 | BN14: =IF(AND(BN$7="○",$A14>=BN$8,$A14<=BN$9),IF(SUM(BN$10:BN13)-ROUNDDOWN($M14*BN$5/100,0)<-BN$6,-BN$6-SUM(BN$10:BN13),-ROUNDDOWN($M14*BN$5/100,0)),0) -> 0 | BO14: =IF(AND(BO$7="○",$A14>=BO$8,$A14<=BO$9),IF(SUM(BO$10:BO13)-ROUNDDOWN($M14*BO$5/100,0)<-BO$6,-BO$6-SUM(BO$10:BO13),-ROUNDDOWN($M14*BO$5/100,0)),0) -> 0 | BP14: =IF(AND(BP$7="○",$A14>=BP$8,$A14<=BP$9),IF(SUM(BP$10:BP13)-ROUNDDOWN($M14*BP$5/100,0)<-BP$6,-BP$6-SUM(BP$10:BP13),-ROUNDDOWN($M14*BP$5/100,0)),0) -> 0 | BQ14: =IF(AND(BQ$7="○",$A14>=BQ$8,$A14<=BQ$9),IF(SUM(BQ$10:BQ13)-ROUNDDOWN($L14*BQ$5/100,0)<-BQ$6,-BQ$6-SUM(BQ$10:BQ13),-ROUNDDOWN($L14*BQ$5/100,0)),0) -> 0 | BR14: =IF(AND(BR$7="○",$A14>=BR$8,$A14<=BR$9),IF(SUM(BR$10:BR13)-ROUNDDOWN($M14*BR$5/100,0)<-BR$6,-BR$6-SUM(BR$10:BR13),-ROUNDDOWN($M14*BR$5/100,0)),0) -> 0 | BS14: =IF(AND(BS$7="○",$A14>=BS$8,$A14<=BS$9),IF(SUM(BS$10:BS13)-ROUNDDOWN($M14*BS$5/100,0)<-BS$6,-BS$6-SUM(BS$10:BS13),-ROUNDDOWN($M14*BS$5/100,0)),0) -> 0 | BT14: =IF(AND(BT$7="○",$A14>=BT$8,$A14<=BT$9),IF(SUM(BT$10:BT13)-ROUNDDOWN($M14*BT$5/100,0)<-BT$6,-BT$6-SUM(BT$10:BT13),-ROUNDDOWN($M14*BT$5/100,0)),0) -> 0 | BU14: =IF(AND(BU$7="○",$A14>=BU$8,$A14<=BU$9),IF(SUM(BU$10:BU13)-ROUNDDOWN($M14*BU$5/100,0)<-BU$6,-BU$6-SUM(BU$10:BU13),-ROUNDDOWN($M14*BU$5/100,0)),0) -> 0 | BV14: =IF(AND(BV$7="○",$A14>=BV$8,$A14<=BV$9),IF(SUM(BV$10:BV13)-ROUNDDOWN($M14*BV$5/100,0)<-BV$6,-BV$6-SUM(BV$10:BV13),-ROUNDDOWN($M14*BV$5/100,0)),0) -> 0 | BW14: =IF(AND(BW$7="○",$A14>=BW$8,$A14<=BW$9),IF(SUM(BW$10:BW13)-ROUNDDOWN($M14*BW$5/100,0)<-BW$6,-BW$6-SUM(BW$10:BW13),-ROUNDDOWN($M14*BW$5/100,0)),0) -> 0 | BX14: =IF(AND(T14="○",$A14>=BX$8,$A14<=BX$9),IF(SUM(BX$10:BX13)-ROUNDDOWN($K14*BX$5/100,0)<-BX$6,-BX$6-SUM(BX$10:BX13),-ROUNDDOWN($K14*BX$5/100,0)),0) -> 0 | BY14: =IF(AND(U14="○",$A14>=BY$8,$A14<=BY$9),IF(SUM(BY$10:BY13)-ROUNDDOWN($K14*BY$5/100,0)<-BY$6,-BY$6-SUM(BY$10:BY13),-ROUNDDOWN($K14*BY$5/100,0)),0) -> 0 | BZ14: =IF(AND(V14="○",$A14>=BZ$8,$A14<=BZ$9),IF(SUM(BZ$10:BZ13)-ROUNDDOWN($K14*BZ$5/100,0)<-BZ$6,-BZ$6-SUM(BZ$10:BZ13),-ROUNDDOWN($K14*BZ$5/100,0)),0) -> 0 | CA14: =IF(AND(W14="○",$A14>=CA$8,$A14<=CA$9),IF(SUM(CA$10:CA13)-ROUNDDOWN($K14*CA$5/100,0)<-CA$6,-CA$6-SUM(CA$10:CA13),-ROUNDDOWN($K14*CA$5/100,0)),0) -> 0 | CG14: =+SUM(AJ14:CF14,BC14,BE14,AZ14,BA14,BG14,BI14) -> 0 | CH14: =+CG14+N14 -> 0 | CI14: =IFERROR(ROUNDDOWN((CH14/G14),0),0) -> 0 | CO14: =IFERROR(CN14-CI14,0) -> 0 | CP14: =IFERROR(CN14/CI14,0) -> 0 | CR14: =+CO14*G14 -> 0 | CT14: =INDEX([2]マスタ!$A:$A,MATCH(D14,[2]マスタ!$C:$C,0)) -> #N/A | CU14: =IFERROR(TEXT(TODAY(),"yyyymmdd")&"_"&ROUNDDOWN(H14+I14,0)&"-"&ROUNDDOWN(CI14,0),"") -> 20260620_0-0
G15: 1 | H15: =+F15*G15 -> 0 | K15: =+ROUNDDOWN((H15+I15)/100,0)*100 -> 0 | L15: =+ROUNDDOWN((H15+I15)/1.1/100,0)*100 -> 0 | M15: =+ROUNDDOWN((H15+I15)/1.1/200,0)*200 -> 0 | N15: =+H15+I15+J15 -> 0 | O15: =IF(OR(WEEKDAY($A15,2)=2,WEEKDAY($A15,2)=4),"○","✕") -> ✕ | P15: =+IF(MOD(TEXT($A15,"DD"),5)=0,"○","✕") -> ○ | Q15: =+IF((TEXT($A15,"DD")+0)=1,"○","✕") -> ✕ | R15: =+IF((TEXT($A15,"DD")+0)=18,"○","✕") -> ✕ | S15: 0 | T15: ✕ | U15: ✕ | V15: ✕ | W15: ✕ | X15: ○ | Y15: ✕ | Z15: ✕ | AA15: ✕ | AB15: ✕ | AC15: ✕ | AD15: =+IF(ISERROR(VLOOKUP($B15,AD$10:AD14,1,0)),IF(AND($N15>=1000,$A15>=AO$8,$A15<=AO$9),$B15,""),"") | AE15: =+IF(ISERROR(VLOOKUP($B15,AE$10:AE14,1,0)),IF(AND($N15>=1000,$A15>=AP$8,$A15<=AP$9),$B15,""),"") | AF15: =+IF(ISERROR(VLOOKUP($B15,AF$10:AF14,1,0)),IF(AND($N15>=1000,$A15>=AQ$8,$A15<=AQ$9),$B15,""),"") | AG15: =+IF(ISERROR(VLOOKUP($B15,AG$10:AG14,1,0)),IF(AND($N15>=1000,$A15>=AR$8,$A15<=AR$9),$B15,""),"") | AI15: 0 | AJ15: =IF(AND(AJ$7="○",$A15>=AJ$8,$A15<=AJ$9),IF(SUM(AJ$10:AJ14)-ROUNDDOWN($K15*AJ$5/100,0)<-AJ$6,-AJ$6-SUM(AJ$10:AJ14),-ROUNDDOWN($K15*AJ$5/100,0)),0) -> 0 | AK15: =IF(AND(AK$7="○",$A15>=AK$8,$A15<=AK$9),IF(SUM(AK$10:AK14)-ROUNDDOWN($L15*AK$5/100,0)<-AK$6,-AK$6-SUM(AK$10:AK14),-ROUNDDOWN($L15*AK$5/100,0)),0) -> 0 | AL15: =IF(AND(AL$7="○",$A15>=AL$8,$A15<=AL$9),IF(SUM(AL$10:AL14)-ROUNDDOWN($N15*AL$5/100,0)<-AL$6,-AL$6-SUM(AL$10:AL14),-ROUNDDOWN($N15*AL$5/100,0)),0) -> 0 | AM15: =IF(AND(AM$7="○",$A15>=AM$8,$A15<=AM$9),IF(SUM(AM$10:AM14)-ROUNDDOWN($L15*AM$5/100,0)<-AM$6,-AM$6-SUM(AM$10:AM14),-ROUNDDOWN($L15*AM$5/100,0)),0) -> 0 | AN15: =IF(AND(AN$7="○",$A15>=AN$8,$A15<=AN$9),IF(SUM(AN$10:AN14)-ROUNDDOWN($M15*AN$5/100,0)<-AN$6,-AN$6-SUM(AN$10:AN14),-ROUNDDOWN($M15*AN$5/100,0)),0) -> 0 | AO15: =IF(AND($A15>=AO$8,$A15<=AO$9),IF(SUM(AO$10:AO14)-ROUNDDOWN($K15*AO$5/100,0)<-AO$6,-AO$6-SUM(AO$10:AO14),-ROUNDDOWN($K15*AO$5/100,0)),0) -> 0 | AP15: =IF(AND($A15>=AP$8,$A15<=AP$9),IF(SUM(AP$10:AP14)-ROUNDDOWN($K15*AP$5/100,0)<-AP$6,-AP$6-SUM(AP$10:AP14),-ROUNDDOWN($K15*AP$5/100,0)),0) -> 0 | AQ15: =IF(AND($A15>=AQ$8,$A15<=AQ$9),IF(SUM(AQ$10:AQ14)-ROUNDDOWN($K15*AQ$5/100,0)<-AQ$6,-AQ$6-SUM(AQ$10:AQ14),-ROUNDDOWN($K15*AQ$5/100,0)),0) -> 0 | AR15: =IF(AND($A15>=AR$8,$A15<=AR$9),IF(SUM(AR$10:AR14)-ROUNDDOWN($K15*AR$5/100,0)<-AR$6,-AR$6-SUM(AR$10:AR14),-ROUNDDOWN($K15*AR$5/100,0)),0) -> 0 | AS15: =IF(SUMIFS(AS$10:AS14,$A$10:$A14,$A15)-ROUNDDOWN($K15*$S15/100,0)<-$S15*1000,-$S15*1000-SUMIFS(AS$10:AS14,$A$10:$A14,$A15),-ROUNDDOWN($K15*$S15/100,0)) -> 0 | AT15: =IF(AND(X15="○",$A15>=AT$8,$A15<=AT$9,K15>=3980),IF(SUM(AT$10:AT14)-ROUNDDOWN($K15*AT$5/100,0)<-AT$6,-AT$6-SUM(AT$10:AT14),-ROUNDDOWN($K15*AT$5/100,0)),0) -> 0 | AU15: =IF(O15="○",IF(SUM(AU$10:AU14)-ROUNDDOWN($K15*AU$5/100,0)<-AU$6,-AU$6-SUM(AU$10:AU14),-ROUNDDOWN($K15*AU$5/100,0)),0) -> 0 | AV15: =IF(P15="○",IF(SUM(AV$10:AV14)-ROUNDDOWN($K15*AV$5/100,0)<-AV$6,-AV$6-SUM(AV$10:AV14),-ROUNDDOWN($K15*AV$5/100,0)),0) -> 0 | AW15: =IF(Q15="○",IF(SUM(AW$10:AW14)-ROUNDDOWN($K15*AW$5/100,0)<-AW$6,-AW$6-SUM(AW$10:AW14),-ROUNDDOWN($K15*AW$5/100,0)),0) -> 0 | AX15: =IF(R15="○",IF(SUM(AX$10:AX14)-ROUNDDOWN($K15*AX$5/100,0)<-AX$6,-AX$6-SUM(AX$10:AX14),-ROUNDDOWN($K15*AX$5/100,0)),0) -> 0 | AY15: 0 | AZ15: =-ROUNDDOWN($K15*AY15/100,0) -> 0 | BA15: =-ROUNDDOWN($K15*AI15/100,0) -> 0 | BC15: =-ROUNDDOWN($K15*BB15/100,0) -> 0 | BD15: 0 | BE15: =-ROUNDDOWN($K15*BD15/100,0) -> 0 | BF15: 0 | BG15: =-ROUNDDOWN($K15*BF15/100,0) -> 0 | BH15: 0 | BI15: =-ROUNDDOWN($K15*BH15/100,0) -> 0 | BJ15: =IF(AND(BJ$7="○",$A15>=BJ$8,$A15<=BJ$9),IF(SUM(BJ$10:BJ14)-ROUNDDOWN($M15*BJ$5/100,0)<-BJ$6,-BJ$6-SUM(BJ$10:BJ14),-ROUNDDOWN($M15*BJ$5/100,0)),0) -> 0 | BK15: =IF(AND(BK$7="○",$A15>=BK$8,$A15<=BK$9),IF(SUM(BK$10:BK14)-ROUNDDOWN($L15*BK$5/100,0)<-BK$6,-BK$6-SUM(BK$10:BK14),-ROUNDDOWN($L15*BK$5/100,0)),0) -> 0 | BL15: =IF(AND(BL$7="○",$A15>=BL$8,$A15<=BL$9),IF(SUM(BL$10:BL14)-ROUNDDOWN($L15*BL$5/100,0)<-BL$6,-BL$6-SUM(BL$10:BL14),-ROUNDDOWN($L15*BL$5/100,0)),0) -> 0 | BM15: =IF(AND(BM$7="○",$A15>=BM$8,$A15<=BM$9),IF(SUM(BM$10:BM14)-ROUNDDOWN($M15*BM$5/100,0)<-BM$6,-BM$6-SUM(BM$10:BM14),-ROUNDDOWN($M15*BM$5/100,0)),0) -> 0 | BN15: =IF(AND(BN$7="○",$A15>=BN$8,$A15<=BN$9),IF(SUM(BN$10:BN14)-ROUNDDOWN($M15*BN$5/100,0)<-BN$6,-BN$6-SUM(BN$10:BN14),-ROUNDDOWN($M15*BN$5/100,0)),0) -> 0 | BO15: =IF(AND(BO$7="○",$A15>=BO$8,$A15<=BO$9),IF(SUM(BO$10:BO14)-ROUNDDOWN($M15*BO$5/100,0)<-BO$6,-BO$6-SUM(BO$10:BO14),-ROUNDDOWN($M15*BO$5/100,0)),0) -> 0 | BP15: =IF(AND(BP$7="○",$A15>=BP$8,$A15<=BP$9),IF(SUM(BP$10:BP14)-ROUNDDOWN($M15*BP$5/100,0)<-BP$6,-BP$6-SUM(BP$10:BP14),-ROUNDDOWN($M15*BP$5/100,0)),0) -> 0 | BQ15: =IF(AND(BQ$7="○",$A15>=BQ$8,$A15<=BQ$9),IF(SUM(BQ$10:BQ14)-ROUNDDOWN($L15*BQ$5/100,0)<-BQ$6,-BQ$6-SUM(BQ$10:BQ14),-ROUNDDOWN($L15*BQ$5/100,0)),0) -> 0 | BR15: =IF(AND(BR$7="○",$A15>=BR$8,$A15<=BR$9),IF(SUM(BR$10:BR14)-ROUNDDOWN($M15*BR$5/100,0)<-BR$6,-BR$6-SUM(BR$10:BR14),-ROUNDDOWN($M15*BR$5/100,0)),0) -> 0 | BS15: =IF(AND(BS$7="○",$A15>=BS$8,$A15<=BS$9),IF(SUM(BS$10:BS14)-ROUNDDOWN($M15*BS$5/100,0)<-BS$6,-BS$6-SUM(BS$10:BS14),-ROUNDDOWN($M15*BS$5/100,0)),0) -> 0 | BT15: =IF(AND(BT$7="○",$A15>=BT$8,$A15<=BT$9),IF(SUM(BT$10:BT14)-ROUNDDOWN($M15*BT$5/100,0)<-BT$6,-BT$6-SUM(BT$10:BT14),-ROUNDDOWN($M15*BT$5/100,0)),0) -> 0 | BU15: =IF(AND(BU$7="○",$A15>=BU$8,$A15<=BU$9),IF(SUM(BU$10:BU14)-ROUNDDOWN($M15*BU$5/100,0)<-BU$6,-BU$6-SUM(BU$10:BU14),-ROUNDDOWN($M15*BU$5/100,0)),0) -> 0 | BV15: =IF(AND(BV$7="○",$A15>=BV$8,$A15<=BV$9),IF(SUM(BV$10:BV14)-ROUNDDOWN($M15*BV$5/100,0)<-BV$6,-BV$6-SUM(BV$10:BV14),-ROUNDDOWN($M15*BV$5/100,0)),0) -> 0 | BW15: =IF(AND(BW$7="○",$A15>=BW$8,$A15<=BW$9),IF(SUM(BW$10:BW14)-ROUNDDOWN($M15*BW$5/100,0)<-BW$6,-BW$6-SUM(BW$10:BW14),-ROUNDDOWN($M15*BW$5/100,0)),0) -> 0 | BX15: =IF(AND(T15="○",$A15>=BX$8,$A15<=BX$9),IF(SUM(BX$10:BX14)-ROUNDDOWN($K15*BX$5/100,0)<-BX$6,-BX$6-SUM(BX$10:BX14),-ROUNDDOWN($K15*BX$5/100,0)),0) -> 0 | BY15: =IF(AND(U15="○",$A15>=BY$8,$A15<=BY$9),IF(SUM(BY$10:BY14)-ROUNDDOWN($K15*BY$5/100,0)<-BY$6,-BY$6-SUM(BY$10:BY14),-ROUNDDOWN($K15*BY$5/100,0)),0) -> 0 | BZ15: =IF(AND(V15="○",$A15>=BZ$8,$A15<=BZ$9),IF(SUM(BZ$10:BZ14)-ROUNDDOWN($K15*BZ$5/100,0)<-BZ$6,-BZ$6-SUM(BZ$10:BZ14),-ROUNDDOWN($K15*BZ$5/100,0)),0) -> 0 | CA15: =IF(AND(W15="○",$A15>=CA$8,$A15<=CA$9),IF(SUM(CA$10:CA14)-ROUNDDOWN($K15*CA$5/100,0)<-CA$6,-CA$6-SUM(CA$10:CA14),-ROUNDDOWN($K15*CA$5/100,0)),0) -> 0 | CG15: =+SUM(AJ15:CF15,BC15,BE15,AZ15,BA15,BG15,BI15) -> 0 | CH15: =+CG15+N15 -> 0 | CI15: =IFERROR(ROUNDDOWN((CH15/G15),0),0) -> 0 | CO15: =IFERROR(CN15-CI15,0) -> 0 | CP15: =IFERROR(CN15/CI15,0) -> 0 | CR15: =+CO15*G15 -> 0 | CT15: =INDEX([2]マスタ!$A:$A,MATCH(D15,[2]マスタ!$C:$C,0)) -> #N/A | CU15: =IFERROR(TEXT(TODAY(),"yyyymmdd")&"_"&ROUNDDOWN(H15+I15,0)&"-"&ROUNDDOWN(CI15,0),"") -> 20260620_0-0
G16: 1 | H16: =+F16*G16 -> 0 | K16: =+ROUNDDOWN((H16+I16)/100,0)*100 -> 0 | L16: =+ROUNDDOWN((H16+I16)/1.1/100,0)*100 -> 0 | M16: =+ROUNDDOWN((H16+I16)/1.1/200,0)*200 -> 0 | N16: =+H16+I16+J16 -> 0 | O16: =IF(OR(WEEKDAY($A16,2)=2,WEEKDAY($A16,2)=4),"○","✕") -> ✕ | P16: =+IF(MOD(TEXT($A16,"DD"),5)=0,"○","✕") -> ○ | Q16: =+IF((TEXT($A16,"DD")+0)=1,"○","✕") -> ✕ | R16: =+IF((TEXT($A16,"DD")+0)=18,"○","✕") -> ✕ | S16: 0 | T16: ✕ | U16: ✕ | V16: ✕ | W16: ✕ | X16: ○ | Y16: ✕ | Z16: ✕ | AA16: ✕ | AB16: ✕ | AC16: ✕ | AD16: =+IF(ISERROR(VLOOKUP($B16,AD$10:AD15,1,0)),IF(AND($N16>=1000,$A16>=AO$8,$A16<=AO$9),$B16,""),"") | AE16: =+IF(ISERROR(VLOOKUP($B16,AE$10:AE15,1,0)),IF(AND($N16>=1000,$A16>=AP$8,$A16<=AP$9),$B16,""),"") | AF16: =+IF(ISERROR(VLOOKUP($B16,AF$10:AF15,1,0)),IF(AND($N16>=1000,$A16>=AQ$8,$A16<=AQ$9),$B16,""),"") | AG16: =+IF(ISERROR(VLOOKUP($B16,AG$10:AG15,1,0)),IF(AND($N16>=1000,$A16>=AR$8,$A16<=AR$9),$B16,""),"") | AI16: 0 | AJ16: =IF(AND(AJ$7="○",$A16>=AJ$8,$A16<=AJ$9),IF(SUM(AJ$10:AJ15)-ROUNDDOWN($K16*AJ$5/100,0)<-AJ$6,-AJ$6-SUM(AJ$10:AJ15),-ROUNDDOWN($K16*AJ$5/100,0)),0) -> 0 | AK16: =IF(AND(AK$7="○",$A16>=AK$8,$A16<=AK$9),IF(SUM(AK$10:AK15)-ROUNDDOWN($L16*AK$5/100,0)<-AK$6,-AK$6-SUM(AK$10:AK15),-ROUNDDOWN($L16*AK$5/100,0)),0) -> 0 | AL16: =IF(AND(AL$7="○",$A16>=AL$8,$A16<=AL$9),IF(SUM(AL$10:AL15)-ROUNDDOWN($N16*AL$5/100,0)<-AL$6,-AL$6-SUM(AL$10:AL15),-ROUNDDOWN($N16*AL$5/100,0)),0) -> 0 | AM16: =IF(AND(AM$7="○",$A16>=AM$8,$A16<=AM$9),IF(SUM(AM$10:AM15)-ROUNDDOWN($L16*AM$5/100,0)<-AM$6,-AM$6-SUM(AM$10:AM15),-ROUNDDOWN($L16*AM$5/100,0)),0) -> 0 | AN16: =IF(AND(AN$7="○",$A16>=AN$8,$A16<=AN$9),IF(SUM(AN$10:AN15)-ROUNDDOWN($M16*AN$5/100,0)<-AN$6,-AN$6-SUM(AN$10:AN15),-ROUNDDOWN($M16*AN$5/100,0)),0) -> 0 | AO16: =IF(AND($A16>=AO$8,$A16<=AO$9),IF(SUM(AO$10:AO15)-ROUNDDOWN($K16*AO$5/100,0)<-AO$6,-AO$6-SUM(AO$10:AO15),-ROUNDDOWN($K16*AO$5/100,0)),0) -> 0 | AP16: =IF(AND($A16>=AP$8,$A16<=AP$9),IF(SUM(AP$10:AP15)-ROUNDDOWN($K16*AP$5/100,0)<-AP$6,-AP$6-SUM(AP$10:AP15),-ROUNDDOWN($K16*AP$5/100,0)),0) -> 0 | AQ16: =IF(AND($A16>=AQ$8,$A16<=AQ$9),IF(SUM(AQ$10:AQ15)-ROUNDDOWN($K16*AQ$5/100,0)<-AQ$6,-AQ$6-SUM(AQ$10:AQ15),-ROUNDDOWN($K16*AQ$5/100,0)),0) -> 0 | AR16: =IF(AND($A16>=AR$8,$A16<=AR$9),IF(SUM(AR$10:AR15)-ROUNDDOWN($K16*AR$5/100,0)<-AR$6,-AR$6-SUM(AR$10:AR15),-ROUNDDOWN($K16*AR$5/100,0)),0) -> 0 | AS16: =IF(SUMIFS(AS$10:AS15,$A$10:$A15,$A16)-ROUNDDOWN($K16*$S16/100,0)<-$S16*1000,-$S16*1000-SUMIFS(AS$10:AS15,$A$10:$A15,$A16),-ROUNDDOWN($K16*$S16/100,0)) -> 0 | AT16: =IF(AND(X16="○",$A16>=AT$8,$A16<=AT$9,K16>=3980),IF(SUM(AT$10:AT15)-ROUNDDOWN($K16*AT$5/100,0)<-AT$6,-AT$6-SUM(AT$10:AT15),-ROUNDDOWN($K16*AT$5/100,0)),0) -> 0 | AU16: =IF(O16="○",IF(SUM(AU$10:AU15)-ROUNDDOWN($K16*AU$5/100,0)<-AU$6,-AU$6-SUM(AU$10:AU15),-ROUNDDOWN($K16*AU$5/100,0)),0) -> 0 | AV16: =IF(P16="○",IF(SUM(AV$10:AV15)-ROUNDDOWN($K16*AV$5/100,0)<-AV$6,-AV$6-SUM(AV$10:AV15),-ROUNDDOWN($K16*AV$5/100,0)),0) -> 0 | AW16: =IF(Q16="○",IF(SUM(AW$10:AW15)-ROUNDDOWN($K16*AW$5/100,0)<-AW$6,-AW$6-SUM(AW$10:AW15),-ROUNDDOWN($K16*AW$5/100,0)),0) -> 0 | AX16: =IF(R16="○",IF(SUM(AX$10:AX15)-ROUNDDOWN($K16*AX$5/100,0)<-AX$6,-AX$6-SUM(AX$10:AX15),-ROUNDDOWN($K16*AX$5/100,0)),0) -> 0 | AY16: 0 | AZ16: =-ROUNDDOWN($K16*AY16/100,0) -> 0 | BA16: =-ROUNDDOWN($K16*AI16/100,0) -> 0 | BC16: =-ROUNDDOWN($K16*BB16/100,0) -> 0 | BD16: 0 | BE16: =-ROUNDDOWN($K16*BD16/100,0) -> 0 | BF16: 0 | BG16: =-ROUNDDOWN($K16*BF16/100,0) -> 0 | BH16: 0 | BI16: =-ROUNDDOWN($K16*BH16/100,0) -> 0 | BJ16: =IF(AND(BJ$7="○",$A16>=BJ$8,$A16<=BJ$9),IF(SUM(BJ$10:BJ15)-ROUNDDOWN($M16*BJ$5/100,0)<-BJ$6,-BJ$6-SUM(BJ$10:BJ15),-ROUNDDOWN($M16*BJ$5/100,0)),0) -> 0 | BK16: =IF(AND(BK$7="○",$A16>=BK$8,$A16<=BK$9),IF(SUM(BK$10:BK15)-ROUNDDOWN($L16*BK$5/100,0)<-BK$6,-BK$6-SUM(BK$10:BK15),-ROUNDDOWN($L16*BK$5/100,0)),0) -> 0 | BL16: =IF(AND(BL$7="○",$A16>=BL$8,$A16<=BL$9),IF(SUM(BL$10:BL15)-ROUNDDOWN($L16*BL$5/100,0)<-BL$6,-BL$6-SUM(BL$10:BL15),-ROUNDDOWN($L16*BL$5/100,0)),0) -> 0 | BM16: =IF(AND(BM$7="○",$A16>=BM$8,$A16<=BM$9),IF(SUM(BM$10:BM15)-ROUNDDOWN($M16*BM$5/100,0)<-BM$6,-BM$6-SUM(BM$10:BM15),-ROUNDDOWN($M16*BM$5/100,0)),0) -> 0 | BN16: =IF(AND(BN$7="○",$A16>=BN$8,$A16<=BN$9),IF(SUM(BN$10:BN15)-ROUNDDOWN($M16*BN$5/100,0)<-BN$6,-BN$6-SUM(BN$10:BN15),-ROUNDDOWN($M16*BN$5/100,0)),0) -> 0 | BO16: =IF(AND(BO$7="○",$A16>=BO$8,$A16<=BO$9),IF(SUM(BO$10:BO15)-ROUNDDOWN($M16*BO$5/100,0)<-BO$6,-BO$6-SUM(BO$10:BO15),-ROUNDDOWN($M16*BO$5/100,0)),0) -> 0 | BP16: =IF(AND(BP$7="○",$A16>=BP$8,$A16<=BP$9),IF(SUM(BP$10:BP15)-ROUNDDOWN($M16*BP$5/100,0)<-BP$6,-BP$6-SUM(BP$10:BP15),-ROUNDDOWN($M16*BP$5/100,0)),0) -> 0 | BQ16: =IF(AND(BQ$7="○",$A16>=BQ$8,$A16<=BQ$9),IF(SUM(BQ$10:BQ15)-ROUNDDOWN($L16*BQ$5/100,0)<-BQ$6,-BQ$6-SUM(BQ$10:BQ15),-ROUNDDOWN($L16*BQ$5/100,0)),0) -> 0 | BR16: =IF(AND(BR$7="○",$A16>=BR$8,$A16<=BR$9),IF(SUM(BR$10:BR15)-ROUNDDOWN($M16*BR$5/100,0)<-BR$6,-BR$6-SUM(BR$10:BR15),-ROUNDDOWN($M16*BR$5/100,0)),0) -> 0 | BS16: =IF(AND(BS$7="○",$A16>=BS$8,$A16<=BS$9),IF(SUM(BS$10:BS15)-ROUNDDOWN($M16*BS$5/100,0)<-BS$6,-BS$6-SUM(BS$10:BS15),-ROUNDDOWN($M16*BS$5/100,0)),0) -> 0 | BT16: =IF(AND(BT$7="○",$A16>=BT$8,$A16<=BT$9),IF(SUM(BT$10:BT15)-ROUNDDOWN($M16*BT$5/100,0)<-BT$6,-BT$6-SUM(BT$10:BT15),-ROUNDDOWN($M16*BT$5/100,0)),0) -> 0 | BU16: =IF(AND(BU$7="○",$A16>=BU$8,$A16<=BU$9),IF(SUM(BU$10:BU15)-ROUNDDOWN($M16*BU$5/100,0)<-BU$6,-BU$6-SUM(BU$10:BU15),-ROUNDDOWN($M16*BU$5/100,0)),0) -> 0 | BV16: =IF(AND(BV$7="○",$A16>=BV$8,$A16<=BV$9),IF(SUM(BV$10:BV15)-ROUNDDOWN($M16*BV$5/100,0)<-BV$6,-BV$6-SUM(BV$10:BV15),-ROUNDDOWN($M16*BV$5/100,0)),0) -> 0 | BW16: =IF(AND(BW$7="○",$A16>=BW$8,$A16<=BW$9),IF(SUM(BW$10:BW15)-ROUNDDOWN($M16*BW$5/100,0)<-BW$6,-BW$6-SUM(BW$10:BW15),-ROUNDDOWN($M16*BW$5/100,0)),0) -> 0 | BX16: =IF(AND(T16="○",$A16>=BX$8,$A16<=BX$9),IF(SUM(BX$10:BX15)-ROUNDDOWN($K16*BX$5/100,0)<-BX$6,-BX$6-SUM(BX$10:BX15),-ROUNDDOWN($K16*BX$5/100,0)),0) -> 0 | BY16: =IF(AND(U16="○",$A16>=BY$8,$A16<=BY$9),IF(SUM(BY$10:BY15)-ROUNDDOWN($K16*BY$5/100,0)<-BY$6,-BY$6-SUM(BY$10:BY15),-ROUNDDOWN($K16*BY$5/100,0)),0) -> 0 | BZ16: =IF(AND(V16="○",$A16>=BZ$8,$A16<=BZ$9),IF(SUM(BZ$10:BZ15)-ROUNDDOWN($K16*BZ$5/100,0)<-BZ$6,-BZ$6-SUM(BZ$10:BZ15),-ROUNDDOWN($K16*BZ$5/100,0)),0) -> 0 | CA16: =IF(AND(W16="○",$A16>=CA$8,$A16<=CA$9),IF(SUM(CA$10:CA15)-ROUNDDOWN($K16*CA$5/100,0)<-CA$6,-CA$6-SUM(CA$10:CA15),-ROUNDDOWN($K16*CA$5/100,0)),0) -> 0 | CG16: =+SUM(AJ16:CF16,BC16,BE16,AZ16,BA16,BG16,BI16) -> 0 | CH16: =+CG16+N16 -> 0 | CI16: =IFERROR(ROUNDDOWN((CH16/G16),0),0) -> 0 | CO16: =IFERROR(CN16-CI16,0) -> 0 | CP16: =IFERROR(CN16/CI16,0) -> 0 | CR16: =+CO16*G16 -> 0 | CT16: =INDEX([2]マスタ!$A:$A,MATCH(D16,[2]マスタ!$C:$C,0)) -> #N/A | CU16: =IFERROR(TEXT(TODAY(),"yyyymmdd")&"_"&ROUNDDOWN(H16+I16,0)&"-"&ROUNDDOWN(CI16,0),"") -> 20260620_0-0
G17: 1 | H17: =+F17*G17 -> 0 | K17: =+ROUNDDOWN((H17+I17)/100,0)*100 -> 0 | L17: =+ROUNDDOWN((H17+I17)/1.1/100,0)*100 -> 0 | M17: =+ROUNDDOWN((H17+I17)/1.1/200,0)*200 -> 0 | N17: =+H17+I17+J17 -> 0 | O17: =IF(OR(WEEKDAY($A17,2)=2,WEEKDAY($A17,2)=4),"○","✕") -> ✕ | P17: =+IF(MOD(TEXT($A17,"DD"),5)=0,"○","✕") -> ○ | Q17: =+IF((TEXT($A17,"DD")+0)=1,"○","✕") -> ✕ | R17: =+IF((TEXT($A17,"DD")+0)=18,"○","✕") -> ✕ | S17: 0 | T17: ✕ | U17: ✕ | V17: ✕ | W17: ✕ | X17: ○ | Y17: ✕ | Z17: ✕ | AA17: ✕ | AB17: ✕ | AC17: ✕ | AD17: =+IF(ISERROR(VLOOKUP($B17,AD$10:AD16,1,0)),IF(AND($N17>=1000,$A17>=AO$8,$A17<=AO$9),$B17,""),"") | AE17: =+IF(ISERROR(VLOOKUP($B17,AE$10:AE16,1,0)),IF(AND($N17>=1000,$A17>=AP$8,$A17<=AP$9),$B17,""),"") | AF17: =+IF(ISERROR(VLOOKUP($B17,AF$10:AF16,1,0)),IF(AND($N17>=1000,$A17>=AQ$8,$A17<=AQ$9),$B17,""),"") | AG17: =+IF(ISERROR(VLOOKUP($B17,AG$10:AG16,1,0)),IF(AND($N17>=1000,$A17>=AR$8,$A17<=AR$9),$B17,""),"") | AI17: 0 | AJ17: =IF(AND(AJ$7="○",$A17>=AJ$8,$A17<=AJ$9),IF(SUM(AJ$10:AJ16)-ROUNDDOWN($K17*AJ$5/100,0)<-AJ$6,-AJ$6-SUM(AJ$10:AJ16),-ROUNDDOWN($K17*AJ$5/100,0)),0) -> 0 | AK17: =IF(AND(AK$7="○",$A17>=AK$8,$A17<=AK$9),IF(SUM(AK$10:AK16)-ROUNDDOWN($L17*AK$5/100,0)<-AK$6,-AK$6-SUM(AK$10:AK16),-ROUNDDOWN($L17*AK$5/100,0)),0) -> 0 | AL17: =IF(AND(AL$7="○",$A17>=AL$8,$A17<=AL$9),IF(SUM(AL$10:AL16)-ROUNDDOWN($N17*AL$5/100,0)<-AL$6,-AL$6-SUM(AL$10:AL16),-ROUNDDOWN($N17*AL$5/100,0)),0) -> 0 | AM17: =IF(AND(AM$7="○",$A17>=AM$8,$A17<=AM$9),IF(SUM(AM$10:AM16)-ROUNDDOWN($L17*AM$5/100,0)<-AM$6,-AM$6-SUM(AM$10:AM16),-ROUNDDOWN($L17*AM$5/100,0)),0) -> 0 | AN17: =IF(AND(AN$7="○",$A17>=AN$8,$A17<=AN$9),IF(SUM(AN$10:AN16)-ROUNDDOWN($M17*AN$5/100,0)<-AN$6,-AN$6-SUM(AN$10:AN16),-ROUNDDOWN($M17*AN$5/100,0)),0) -> 0 | AO17: =IF(AND($A17>=AO$8,$A17<=AO$9),IF(SUM(AO$10:AO16)-ROUNDDOWN($K17*AO$5/100,0)<-AO$6,-AO$6-SUM(AO$10:AO16),-ROUNDDOWN($K17*AO$5/100,0)),0) -> 0 | AP17: =IF(AND($A17>=AP$8,$A17<=AP$9),IF(SUM(AP$10:AP16)-ROUNDDOWN($K17*AP$5/100,0)<-AP$6,-AP$6-SUM(AP$10:AP16),-ROUNDDOWN($K17*AP$5/100,0)),0) -> 0 | AQ17: =IF(AND($A17>=AQ$8,$A17<=AQ$9),IF(SUM(AQ$10:AQ16)-ROUNDDOWN($K17*AQ$5/100,0)<-AQ$6,-AQ$6-SUM(AQ$10:AQ16),-ROUNDDOWN($K17*AQ$5/100,0)),0) -> 0 | AR17: =IF(AND($A17>=AR$8,$A17<=AR$9),IF(SUM(AR$10:AR16)-ROUNDDOWN($K17*AR$5/100,0)<-AR$6,-AR$6-SUM(AR$10:AR16),-ROUNDDOWN($K17*AR$5/100,0)),0) -> 0 | AS17: =IF(SUMIFS(AS$10:AS16,$A$10:$A16,$A17)-ROUNDDOWN($K17*$S17/100,0)<-$S17*1000,-$S17*1000-SUMIFS(AS$10:AS16,$A$10:$A16,$A17),-ROUNDDOWN($K17*$S17/100,0)) -> 0 | AT17: =IF(AND(X17="○",$A17>=AT$8,$A17<=AT$9,K17>=3980),IF(SUM(AT$10:AT16)-ROUNDDOWN($K17*AT$5/100,0)<-AT$6,-AT$6-SUM(AT$10:AT16),-ROUNDDOWN($K17*AT$5/100,0)),0) -> 0 | AU17: =IF(O17="○",IF(SUM(AU$10:AU16)-ROUNDDOWN($K17*AU$5/100,0)<-AU$6,-AU$6-SUM(AU$10:AU16),-ROUNDDOWN($K17*AU$5/100,0)),0) -> 0 | AV17: =IF(P17="○",IF(SUM(AV$10:AV16)-ROUNDDOWN($K17*AV$5/100,0)<-AV$6,-AV$6-SUM(AV$10:AV16),-ROUNDDOWN($K17*AV$5/100,0)),0) -> 0 | AW17: =IF(Q17="○",IF(SUM(AW$10:AW16)-ROUNDDOWN($K17*AW$5/100,0)<-AW$6,-AW$6-SUM(AW$10:AW16),-ROUNDDOWN($K17*AW$5/100,0)),0) -> 0 | AX17: =IF(R17="○",IF(SUM(AX$10:AX16)-ROUNDDOWN($K17*AX$5/100,0)<-AX$6,-AX$6-SUM(AX$10:AX16),-ROUNDDOWN($K17*AX$5/100,0)),0) -> 0 | AY17: 0 | AZ17: =-ROUNDDOWN($K17*AY17/100,0) -> 0 | BA17: =-ROUNDDOWN($K17*AI17/100,0) -> 0 | BC17: =-ROUNDDOWN($K17*BB17/100,0) -> 0 | BD17: 0 | BE17: =-ROUNDDOWN($K17*BD17/100,0) -> 0 | BF17: 0 | BG17: =-ROUNDDOWN($K17*BF17/100,0) -> 0 | BH17: 0 | BI17: =-ROUNDDOWN($K17*BH17/100,0) -> 0 | BJ17: =IF(AND(BJ$7="○",$A17>=BJ$8,$A17<=BJ$9),IF(SUM(BJ$10:BJ16)-ROUNDDOWN($M17*BJ$5/100,0)<-BJ$6,-BJ$6-SUM(BJ$10:BJ16),-ROUNDDOWN($M17*BJ$5/100,0)),0) -> 0 | BK17: =IF(AND(BK$7="○",$A17>=BK$8,$A17<=BK$9),IF(SUM(BK$10:BK16)-ROUNDDOWN($L17*BK$5/100,0)<-BK$6,-BK$6-SUM(BK$10:BK16),-ROUNDDOWN($L17*BK$5/100,0)),0) -> 0 | BL17: =IF(AND(BL$7="○",$A17>=BL$8,$A17<=BL$9),IF(SUM(BL$10:BL16)-ROUNDDOWN($L17*BL$5/100,0)<-BL$6,-BL$6-SUM(BL$10:BL16),-ROUNDDOWN($L17*BL$5/100,0)),0) -> 0 | BM17: =IF(AND(BM$7="○",$A17>=BM$8,$A17<=BM$9),IF(SUM(BM$10:BM16)-ROUNDDOWN($M17*BM$5/100,0)<-BM$6,-BM$6-SUM(BM$10:BM16),-ROUNDDOWN($M17*BM$5/100,0)),0) -> 0 | BN17: =IF(AND(BN$7="○",$A17>=BN$8,$A17<=BN$9),IF(SUM(BN$10:BN16)-ROUNDDOWN($M17*BN$5/100,0)<-BN$6,-BN$6-SUM(BN$10:BN16),-ROUNDDOWN($M17*BN$5/100,0)),0) -> 0 | BO17: =IF(AND(BO$7="○",$A17>=BO$8,$A17<=BO$9),IF(SUM(BO$10:BO16)-ROUNDDOWN($M17*BO$5/100,0)<-BO$6,-BO$6-SUM(BO$10:BO16),-ROUNDDOWN($M17*BO$5/100,0)),0) -> 0 | BP17: =IF(AND(BP$7="○",$A17>=BP$8,$A17<=BP$9),IF(SUM(BP$10:BP16)-ROUNDDOWN($M17*BP$5/100,0)<-BP$6,-BP$6-SUM(BP$10:BP16),-ROUNDDOWN($M17*BP$5/100,0)),0) -> 0 | BQ17: =IF(AND(BQ$7="○",$A17>=BQ$8,$A17<=BQ$9),IF(SUM(BQ$10:BQ16)-ROUNDDOWN($L17*BQ$5/100,0)<-BQ$6,-BQ$6-SUM(BQ$10:BQ16),-ROUNDDOWN($L17*BQ$5/100,0)),0) -> 0 | BR17: =IF(AND(BR$7="○",$A17>=BR$8,$A17<=BR$9),IF(SUM(BR$10:BR16)-ROUNDDOWN($M17*BR$5/100,0)<-BR$6,-BR$6-SUM(BR$10:BR16),-ROUNDDOWN($M17*BR$5/100,0)),0) -> 0 | BS17: =IF(AND(BS$7="○",$A17>=BS$8,$A17<=BS$9),IF(SUM(BS$10:BS16)-ROUNDDOWN($M17*BS$5/100,0)<-BS$6,-BS$6-SUM(BS$10:BS16),-ROUNDDOWN($M17*BS$5/100,0)),0) -> 0 | BT17: =IF(AND(BT$7="○",$A17>=BT$8,$A17<=BT$9),IF(SUM(BT$10:BT16)-ROUNDDOWN($M17*BT$5/100,0)<-BT$6,-BT$6-SUM(BT$10:BT16),-ROUNDDOWN($M17*BT$5/100,0)),0) -> 0 | BU17: =IF(AND(BU$7="○",$A17>=BU$8,$A17<=BU$9),IF(SUM(BU$10:BU16)-ROUNDDOWN($M17*BU$5/100,0)<-BU$6,-BU$6-SUM(BU$10:BU16),-ROUNDDOWN($M17*BU$5/100,0)),0) -> 0 | BV17: =IF(AND(BV$7="○",$A17>=BV$8,$A17<=BV$9),IF(SUM(BV$10:BV16)-ROUNDDOWN($M17*BV$5/100,0)<-BV$6,-BV$6-SUM(BV$10:BV16),-ROUNDDOWN($M17*BV$5/100,0)),0) -> 0 | BW17: =IF(AND(BW$7="○",$A17>=BW$8,$A17<=BW$9),IF(SUM(BW$10:BW16)-ROUNDDOWN($M17*BW$5/100,0)<-BW$6,-BW$6-SUM(BW$10:BW16),-ROUNDDOWN($M17*BW$5/100,0)),0) -> 0 | BX17: =IF(AND(T17="○",$A17>=BX$8,$A17<=BX$9),IF(SUM(BX$10:BX16)-ROUNDDOWN($K17*BX$5/100,0)<-BX$6,-BX$6-SUM(BX$10:BX16),-ROUNDDOWN($K17*BX$5/100,0)),0) -> 0 | BY17: =IF(AND(U17="○",$A17>=BY$8,$A17<=BY$9),IF(SUM(BY$10:BY16)-ROUNDDOWN($K17*BY$5/100,0)<-BY$6,-BY$6-SUM(BY$10:BY16),-ROUNDDOWN($K17*BY$5/100,0)),0) -> 0 | BZ17: =IF(AND(V17="○",$A17>=BZ$8,$A17<=BZ$9),IF(SUM(BZ$10:BZ16)-ROUNDDOWN($K17*BZ$5/100,0)<-BZ$6,-BZ$6-SUM(BZ$10:BZ16),-ROUNDDOWN($K17*BZ$5/100,0)),0) -> 0 | CA17: =IF(AND(W17="○",$A17>=CA$8,$A17<=CA$9),IF(SUM(CA$10:CA16)-ROUNDDOWN($K17*CA$5/100,0)<-CA$6,-CA$6-SUM(CA$10:CA16),-ROUNDDOWN($K17*CA$5/100,0)),0) -> 0 | CG17: =+SUM(AJ17:CF17,BC17,BE17,AZ17,BA17,BG17,BI17) -> 0 | CH17: =+CG17+N17 -> 0 | CI17: =IFERROR(ROUNDDOWN((CH17/G17),0),0) -> 0 | CO17: =IFERROR(CN17-CI17,0) -> 0 | CP17: =IFERROR(CN17/CI17,0) -> 0 | CR17: =+CO17*G17 -> 0 | CT17: =INDEX([2]マスタ!$A:$A,MATCH(D17,[2]マスタ!$C:$C,0)) -> #N/A | CU17: =IFERROR(TEXT(TODAY(),"yyyymmdd")&"_"&ROUNDDOWN(H17+I17,0)&"-"&ROUNDDOWN(CI17,0),"") -> 20260620_0-0
G18: 1 | H18: =+F18*G18 -> 0 | K18: =+ROUNDDOWN((H18+I18)/100,0)*100 -> 0 | L18: =+ROUNDDOWN((H18+I18)/1.1/100,0)*100 -> 0 | M18: =+ROUNDDOWN((H18+I18)/1.1/200,0)*200 -> 0 | N18: =+H18+I18+J18 -> 0 | O18: =IF(OR(WEEKDAY($A18,2)=2,WEEKDAY($A18,2)=4),"○","✕") -> ✕ | P18: =+IF(MOD(TEXT($A18,"DD"),5)=0,"○","✕") -> ○ | Q18: =+IF((TEXT($A18,"DD")+0)=1,"○","✕") -> ✕ | R18: =+IF((TEXT($A18,"DD")+0)=18,"○","✕") -> ✕ | S18: 0 | T18: ✕ | U18: ✕ | V18: ✕ | W18: ✕ | X18: ○ | Y18: ✕ | Z18: ✕ | AA18: ✕ | AB18: ✕ | AC18: ✕ | AD18: =+IF(ISERROR(VLOOKUP($B18,AD$10:AD17,1,0)),IF(AND($N18>=1000,$A18>=AO$8,$A18<=AO$9),$B18,""),"") | AE18: =+IF(ISERROR(VLOOKUP($B18,AE$10:AE17,1,0)),IF(AND($N18>=1000,$A18>=AP$8,$A18<=AP$9),$B18,""),"") | AF18: =+IF(ISERROR(VLOOKUP($B18,AF$10:AF17,1,0)),IF(AND($N18>=1000,$A18>=AQ$8,$A18<=AQ$9),$B18,""),"") | AG18: =+IF(ISERROR(VLOOKUP($B18,AG$10:AG17,1,0)),IF(AND($N18>=1000,$A18>=AR$8,$A18<=AR$9),$B18,""),"") | AI18: 0 | AJ18: =IF(AND(AJ$7="○",$A18>=AJ$8,$A18<=AJ$9),IF(SUM(AJ$10:AJ17)-ROUNDDOWN($K18*AJ$5/100,0)<-AJ$6,-AJ$6-SUM(AJ$10:AJ17),-ROUNDDOWN($K18*AJ$5/100,0)),0) -> 0 | AK18: =IF(AND(AK$7="○",$A18>=AK$8,$A18<=AK$9),IF(SUM(AK$10:AK17)-ROUNDDOWN($L18*AK$5/100,0)<-AK$6,-AK$6-SUM(AK$10:AK17),-ROUNDDOWN($L18*AK$5/100,0)),0) -> 0 | AL18: =IF(AND(AL$7="○",$A18>=AL$8,$A18<=AL$9),IF(SUM(AL$10:AL17)-ROUNDDOWN($N18*AL$5/100,0)<-AL$6,-AL$6-SUM(AL$10:AL17),-ROUNDDOWN($N18*AL$5/100,0)),0) -> 0 | AM18: =IF(AND(AM$7="○",$A18>=AM$8,$A18<=AM$9),IF(SUM(AM$10:AM17)-ROUNDDOWN($L18*AM$5/100,0)<-AM$6,-AM$6-SUM(AM$10:AM17),-ROUNDDOWN($L18*AM$5/100,0)),0) -> 0 | AN18: =IF(AND(AN$7="○",$A18>=AN$8,$A18<=AN$9),IF(SUM(AN$10:AN17)-ROUNDDOWN($M18*AN$5/100,0)<-AN$6,-AN$6-SUM(AN$10:AN17),-ROUNDDOWN($M18*AN$5/100,0)),0) -> 0 | AO18: =IF(AND($A18>=AO$8,$A18<=AO$9),IF(SUM(AO$10:AO17)-ROUNDDOWN($K18*AO$5/100,0)<-AO$6,-AO$6-SUM(AO$10:AO17),-ROUNDDOWN($K18*AO$5/100,0)),0) -> 0 | AP18: =IF(AND($A18>=AP$8,$A18<=AP$9),IF(SUM(AP$10:AP17)-ROUNDDOWN($K18*AP$5/100,0)<-AP$6,-AP$6-SUM(AP$10:AP17),-ROUNDDOWN($K18*AP$5/100,0)),0) -> 0 | AQ18: =IF(AND($A18>=AQ$8,$A18<=AQ$9),IF(SUM(AQ$10:AQ17)-ROUNDDOWN($K18*AQ$5/100,0)<-AQ$6,-AQ$6-SUM(AQ$10:AQ17),-ROUNDDOWN($K18*AQ$5/100,0)),0) -> 0 | AR18: =IF(AND($A18>=AR$8,$A18<=AR$9),IF(SUM(AR$10:AR17)-ROUNDDOWN($K18*AR$5/100,0)<-AR$6,-AR$6-SUM(AR$10:AR17),-ROUNDDOWN($K18*AR$5/100,0)),0) -> 0 | AS18: =IF(SUMIFS(AS$10:AS17,$A$10:$A17,$A18)-ROUNDDOWN($K18*$S18/100,0)<-$S18*1000,-$S18*1000-SUMIFS(AS$10:AS17,$A$10:$A17,$A18),-ROUNDDOWN($K18*$S18/100,0)) -> 0 | AT18: =IF(AND(X18="○",$A18>=AT$8,$A18<=AT$9,K18>=3980),IF(SUM(AT$10:AT17)-ROUNDDOWN($K18*AT$5/100,0)<-AT$6,-AT$6-SUM(AT$10:AT17),-ROUNDDOWN($K18*AT$5/100,0)),0) -> 0 | AU18: =IF(O18="○",IF(SUM(AU$10:AU17)-ROUNDDOWN($K18*AU$5/100,0)<-AU$6,-AU$6-SUM(AU$10:AU17),-ROUNDDOWN($K18*AU$5/100,0)),0) -> 0 | AV18: =IF(P18="○",IF(SUM(AV$10:AV17)-ROUNDDOWN($K18*AV$5/100,0)<-AV$6,-AV$6-SUM(AV$10:AV17),-ROUNDDOWN($K18*AV$5/100,0)),0) -> 0 | AW18: =IF(Q18="○",IF(SUM(AW$10:AW17)-ROUNDDOWN($K18*AW$5/100,0)<-AW$6,-AW$6-SUM(AW$10:AW17),-ROUNDDOWN($K18*AW$5/100,0)),0) -> 0 | AX18: =IF(R18="○",IF(SUM(AX$10:AX17)-ROUNDDOWN($K18*AX$5/100,0)<-AX$6,-AX$6-SUM(AX$10:AX17),-ROUNDDOWN($K18*AX$5/100,0)),0) -> 0 | AY18: 0 | AZ18: =-ROUNDDOWN($K18*AY18/100,0) -> 0 | BA18: =-ROUNDDOWN($K18*AI18/100,0) -> 0 | BC18: =-ROUNDDOWN($K18*BB18/100,0) -> 0 | BD18: 0 | BE18: =-ROUNDDOWN($K18*BD18/100,0) -> 0 | BF18: 0 | BG18: =-ROUNDDOWN($K18*BF18/100,0) -> 0 | BH18: 0 | BI18: =-ROUNDDOWN($K18*BH18/100,0) -> 0 | BJ18: =IF(AND(BJ$7="○",$A18>=BJ$8,$A18<=BJ$9),IF(SUM(BJ$10:BJ17)-ROUNDDOWN($M18*BJ$5/100,0)<-BJ$6,-BJ$6-SUM(BJ$10:BJ17),-ROUNDDOWN($M18*BJ$5/100,0)),0) -> 0 | BK18: =IF(AND(BK$7="○",$A18>=BK$8,$A18<=BK$9),IF(SUM(BK$10:BK17)-ROUNDDOWN($L18*BK$5/100,0)<-BK$6,-BK$6-SUM(BK$10:BK17),-ROUNDDOWN($L18*BK$5/100,0)),0) -> 0 | BL18: =IF(AND(BL$7="○",$A18>=BL$8,$A18<=BL$9),IF(SUM(BL$10:BL17)-ROUNDDOWN($L18*BL$5/100,0)<-BL$6,-BL$6-SUM(BL$10:BL17),-ROUNDDOWN($L18*BL$5/100,0)),0) -> 0 | BM18: =IF(AND(BM$7="○",$A18>=BM$8,$A18<=BM$9),IF(SUM(BM$10:BM17)-ROUNDDOWN($M18*BM$5/100,0)<-BM$6,-BM$6-SUM(BM$10:BM17),-ROUNDDOWN($M18*BM$5/100,0)),0) -> 0 | BN18: =IF(AND(BN$7="○",$A18>=BN$8,$A18<=BN$9),IF(SUM(BN$10:BN17)-ROUNDDOWN($M18*BN$5/100,0)<-BN$6,-BN$6-SUM(BN$10:BN17),-ROUNDDOWN($M18*BN$5/100,0)),0) -> 0 | BO18: =IF(AND(BO$7="○",$A18>=BO$8,$A18<=BO$9),IF(SUM(BO$10:BO17)-ROUNDDOWN($M18*BO$5/100,0)<-BO$6,-BO$6-SUM(BO$10:BO17),-ROUNDDOWN($M18*BO$5/100,0)),0) -> 0 | BP18: =IF(AND(BP$7="○",$A18>=BP$8,$A18<=BP$9),IF(SUM(BP$10:BP17)-ROUNDDOWN($M18*BP$5/100,0)<-BP$6,-BP$6-SUM(BP$10:BP17),-ROUNDDOWN($M18*BP$5/100,0)),0) -> 0 | BQ18: =IF(AND(BQ$7="○",$A18>=BQ$8,$A18<=BQ$9),IF(SUM(BQ$10:BQ17)-ROUNDDOWN($L18*BQ$5/100,0)<-BQ$6,-BQ$6-SUM(BQ$10:BQ17),-ROUNDDOWN($L18*BQ$5/100,0)),0) -> 0 | BR18: =IF(AND(BR$7="○",$A18>=BR$8,$A18<=BR$9),IF(SUM(BR$10:BR17)-ROUNDDOWN($M18*BR$5/100,0)<-BR$6,-BR$6-SUM(BR$10:BR17),-ROUNDDOWN($M18*BR$5/100,0)),0) -> 0 | BS18: =IF(AND(BS$7="○",$A18>=BS$8,$A18<=BS$9),IF(SUM(BS$10:BS17)-ROUNDDOWN($M18*BS$5/100,0)<-BS$6,-BS$6-SUM(BS$10:BS17),-ROUNDDOWN($M18*BS$5/100,0)),0) -> 0 | BT18: =IF(AND(BT$7="○",$A18>=BT$8,$A18<=BT$9),IF(SUM(BT$10:BT17)-ROUNDDOWN($M18*BT$5/100,0)<-BT$6,-BT$6-SUM(BT$10:BT17),-ROUNDDOWN($M18*BT$5/100,0)),0) -> 0 | BU18: =IF(AND(BU$7="○",$A18>=BU$8,$A18<=BU$9),IF(SUM(BU$10:BU17)-ROUNDDOWN($M18*BU$5/100,0)<-BU$6,-BU$6-SUM(BU$10:BU17),-ROUNDDOWN($M18*BU$5/100,0)),0) -> 0 | BV18: =IF(AND(BV$7="○",$A18>=BV$8,$A18<=BV$9),IF(SUM(BV$10:BV17)-ROUNDDOWN($M18*BV$5/100,0)<-BV$6,-BV$6-SUM(BV$10:BV17),-ROUNDDOWN($M18*BV$5/100,0)),0) -> 0 | BW18: =IF(AND(BW$7="○",$A18>=BW$8,$A18<=BW$9),IF(SUM(BW$10:BW17)-ROUNDDOWN($M18*BW$5/100,0)<-BW$6,-BW$6-SUM(BW$10:BW17),-ROUNDDOWN($M18*BW$5/100,0)),0) -> 0 | BX18: =IF(AND(T18="○",$A18>=BX$8,$A18<=BX$9),IF(SUM(BX$10:BX17)-ROUNDDOWN($K18*BX$5/100,0)<-BX$6,-BX$6-SUM(BX$10:BX17),-ROUNDDOWN($K18*BX$5/100,0)),0) -> 0 | BY18: =IF(AND(U18="○",$A18>=BY$8,$A18<=BY$9),IF(SUM(BY$10:BY17)-ROUNDDOWN($K18*BY$5/100,0)<-BY$6,-BY$6-SUM(BY$10:BY17),-ROUNDDOWN($K18*BY$5/100,0)),0) -> 0 | BZ18: =IF(AND(V18="○",$A18>=BZ$8,$A18<=BZ$9),IF(SUM(BZ$10:BZ17)-ROUNDDOWN($K18*BZ$5/100,0)<-BZ$6,-BZ$6-SUM(BZ$10:BZ17),-ROUNDDOWN($K18*BZ$5/100,0)),0) -> 0 | CA18: =IF(AND(W18="○",$A18>=CA$8,$A18<=CA$9),IF(SUM(CA$10:CA17)-ROUNDDOWN($K18*CA$5/100,0)<-CA$6,-CA$6-SUM(CA$10:CA17),-ROUNDDOWN($K18*CA$5/100,0)),0) -> 0 | CG18: =+SUM(AJ18:CF18,BC18,BE18,AZ18,BA18,BG18,BI18) -> 0 | CH18: =+CG18+N18 -> 0 | CI18: =IFERROR(ROUNDDOWN((CH18/G18),0),0) -> 0 | CO18: =IFERROR(CN18-CI18,0) -> 0 | CP18: =IFERROR(CN18/CI18,0) -> 0 | CR18: =+CO18*G18 -> 0 | CT18: =INDEX([2]マスタ!$A:$A,MATCH(D18,[2]マスタ!$C:$C,0)) -> #N/A | CU18: =IFERROR(TEXT(TODAY(),"yyyymmdd")&"_"&ROUNDDOWN(H18+I18,0)&"-"&ROUNDDOWN(CI18,0),"") -> 20260620_0-0
